Workbook

Sheet 财富指数—趋势
B1: CBA11411.CS | C1: CBA11421.CS | D1: CBA11431.CS | E1: CBA11441.CS | F1: CBA11451.CS | G1: CBA11461.CS
B2: 中债AA+信用债财富1年指数 | C2: 中债AA+信用债财富3年指数 | D2: 中债AA+信用债财富5年指数 | E2: 中债AA+信用债财富7年指数 | F2: 中债AA+信用债财富10年指数 | G2: 中债AA+信用债财富10年以上指数 | H2: 短端财富指数平均 | I2: 长端财富指数平均
A3: =信用曲线—价格!A3 -> 44565 | B3: =[1]!i_dq_close($B$1,A3) -> 144.2304 | C3: =[1]!i_dq_close($C$1,A3) -> 155.7679 | D3: =[1]!i_dq_close($D$1,A3) -> 163.8279 | E3: =[1]!i_dq_close($E$1,A3) -> 170.3044 | F3: =[1]!i_dq_close($F$1,A3) -> 172.2035 | G3: =[1]!i_dq_close($G$1,A3) -> 178.4097 | H3: =AVERAGE(B3:D3) -> 154.60873 | I3: =AVERAGE(E3:G3) -> 173.6392
A4: =信用曲线—价格!A4 -> 44566 | B4: =[1]!i_dq_close($B$1,A4) -> 144.2481 | C4: =[1]!i_dq_close($C$1,A4) -> 155.7958 | D4: =[1]!i_dq_close($D$1,A4) -> 163.845 | E4: =[1]!i_dq_close($E$1,A4) -> 170.3049 | F4: =[1]!i_dq_close($F$1,A4) -> 172.2178 | G4: =[1]!i_dq_close($G$1,A4) -> 178.4319 | H4: =AVERAGE(B4:D4) -> 154.62963 | I4: =AVERAGE(E4:G4) -> 173.65153
A5: =信用曲线—价格!A5 -> 44567 | B5: =[1]!i_dq_close($B$1,A5) -> 144.2627 | C5: =[1]!i_dq_close($C$1,A5) -> 155.8174 | D5: =[1]!i_dq_close($D$1,A5) -> 163.8485 | E5: =[1]!i_dq_close($E$1,A5) -> 170.3214 | F5: =[1]!i_dq_close($F$1,A5) -> 172.2515 | G5: =[1]!i_dq_close($G$1,A5) -> 178.5159 | H5: =AVERAGE(B5:D5) -> 154.64287 | I5: =AVERAGE(E5:G5) -> 173.69627
A6: =信用曲线—价格!A6 -> 44568 | B6: =[1]!i_dq_close($B$1,A6) -> 144.2797 | C6: =[1]!i_dq_close($C$1,A6) -> 155.8384 | D6: =[1]!i_dq_close($D$1,A6) -> 163.8622 | E6: =[1]!i_dq_close($E$1,A6) -> 170.305 | F6: =[1]!i_dq_close($F$1,A6) -> 172.248 | G6: =[1]!i_dq_close($G$1,A6) -> 178.4655 | H6: =AVERAGE(B6:D6) -> 154.6601 | I6: =AVERAGE(E6:G6) -> 173.67283
A7: =信用曲线—价格!A7 -> 44571 | B7: =[1]!i_dq_close($B$1,A7) -> 144.3165 | C7: =[1]!i_dq_close($C$1,A7) -> 155.9212 | D7: =[1]!i_dq_close($D$1,A7) -> 163.9398 | E7: =[1]!i_dq_close($E$1,A7) -> 170.3679 | F7: =[1]!i_dq_close($F$1,A7) -> 172.3381 | G7: =[1]!i_dq_close($G$1,A7) -> 178.5027 | H7: =AVERAGE(B7:D7) -> 154.72583 | I7: =AVERAGE(E7:G7) -> 173.73623
A8: =信用曲线—价格!A8 -> 44572 | B8: =[1]!i_dq_close($B$1,A8) -> 144.3385 | C8: =[1]!i_dq_close($C$1,A8) -> 155.9704 | D8: =[1]!i_dq_close($D$1,A8) -> 163.9983 | E8: =[1]!i_dq_close($E$1,A8) -> 170.4709 | F8: =[1]!i_dq_close($F$1,A8) -> 172.4367 | G8: =[1]!i_dq_close($G$1,A8) -> 178.5653 | H8: =AVERAGE(B8:D8) -> 154.76907 | I8: =AVERAGE(E8:G8) -> 173.8243
A9: =信用曲线—价格!A9 -> 44573 | B9: =[1]!i_dq_close($B$1,A9) -> 144.3595 | C9: =[1]!i_dq_close($C$1,A9) -> 156.012 | D9: =[1]!i_dq_close($D$1,A9) -> 164.0328 | E9: =[1]!i_dq_close($E$1,A9) -> 170.4897 | F9: =[1]!i_dq_close($F$1,A9) -> 172.5135 | G9: =[1]!i_dq_close($G$1,A9) -> 178.688 | H9: =AVERAGE(B9:D9) -> 154.80143 | I9: =AVERAGE(E9:G9) -> 173.89707
A10: =信用曲线—价格!A10 -> 44574 | B10: =[1]!i_dq_close($B$1,A10) -> 144.3743 | C10: =[1]!i_dq_close($C$1,A10) -> 156.0471 | D10: =[1]!i_dq_close($D$1,A10) -> 164.0711 | E10: =[1]!i_dq_close($E$1,A10) -> 170.5159 | F10: =[1]!i_dq_close($F$1,A10) -> 172.556 | G10: =[1]!i_dq_close($G$1,A10) -> 178.7727 | H10: =AVERAGE(B10:D10) -> 154.83083 | I10: =AVERAGE(E10:G10) -> 173.9482
A11: =信用曲线—价格!A11 -> 44575 | B11: =[1]!i_dq_close($B$1,A11) -> 144.3884 | C11: =[1]!i_dq_close($C$1,A11) -> 156.0652 | D11: =[1]!i_dq_close($D$1,A11) -> 164.0881 | E11: =[1]!i_dq_close($E$1,A11) -> 170.5475 | F11: =[1]!i_dq_close($F$1,A11) -> 172.6225 | G11: =[1]!i_dq_close($G$1,A11) -> 178.8624 | H11: =AVERAGE(B11:D11) -> 154.84723 | I11: =AVERAGE(E11:G11) -> 174.0108
A12: =信用曲线—价格!A12 -> 44578 | B12: =[1]!i_dq_close($B$1,A12) -> 144.4353 | C12: =[1]!i_dq_close($C$1,A12) -> 156.1625 | D12: =[1]!i_dq_close($D$1,A12) -> 164.2013 | E12: =[1]!i_dq_close($E$1,A12) -> 170.6527 | F12: =[1]!i_dq_close($F$1,A12) -> 172.6634 | G12: =[1]!i_dq_close($G$1,A12) -> 178.7876 | H12: =AVERAGE(B12:D12) -> 154.93303 | I12: =AVERAGE(E12:G12) -> 174.03457
A13: =信用曲线—价格!A13 -> 44579 | B13: =[1]!i_dq_close($B$1,A13) -> 144.4593 | C13: =[1]!i_dq_close($C$1,A13) -> 156.231 | D13: =[1]!i_dq_close($D$1,A13) -> 164.2731 | E13: =[1]!i_dq_close($E$1,A13) -> 170.687 | F13: =[1]!i_dq_close($F$1,A13) -> 172.7273 | G13: =[1]!i_dq_close($G$1,A13) -> 178.8937 | H13: =AVERAGE(B13:D13) -> 154.9878 | I13: =AVERAGE(E13:G13) -> 174.10267
A14: =信用曲线—价格!A14 -> 44580 | B14: =[1]!i_dq_close($B$1,A14) -> 144.5005 | C14: =[1]!i_dq_close($C$1,A14) -> 156.3476 | D14: =[1]!i_dq_close($D$1,A14) -> 164.4419 | E14: =[1]!i_dq_close($E$1,A14) -> 170.8859 | F14: =[1]!i_dq_close($F$1,A14) -> 173.0182 | G14: =[1]!i_dq_close($G$1,A14) -> 179.1124 | H14: =AVERAGE(B14:D14) -> 155.09667 | I14: =AVERAGE(E14:G14) -> 174.33883
... A1200: =信用曲线—价格!A1200 -> 46318 | B1200: =[1]!i_dq_close($B$1,A1200) -> 161.8613 | C1200: =[1]!i_dq_close($C$1,A1200) -> 181.5503 | D1200: =[1]!i_dq_close($D$1,A1200) -> 198.0596 | E1200: =[1]!i_dq_close($E$1,A1200) -> 208.7672 | F1200: =[1]!i_dq_close($F$1,A1200) -> 225.877 | G1200: =[1]!i_dq_close($G$1,A1200) -> 241.8025 | H1200: =AVERAGE(B1200:D1200) -> 180.4904 | I1200: =AVERAGE(E1200:G1200) -> 225.48223

Sheet 信用曲线—价格
A1: =[1]!edb() -> Wind
A2: 指标名称 | B2: 中债中短期票据到期收益率(AA+):3年 | C2: 中债中短期票据到期收益率(AA+):5年 | D2: 中债中短期票据到期收益率(AA+):7年 | E2: 中债中短期票据到期收益率(AA+):10年 | F2: 中债国开债到期收益率:7年 | G2: 中债国开债到期收益率:10年 | H2: 7YAA+信用利差 | I2: 10YAA+信用利差
A3: 44565 | B3: 3.1163 | C3: 3.5345 | D3: 3.8168 | E3: 3.9514 | F3: 2.9921 | G3: 3.0791 | H3: =(D3-F3)*100 -> 82.47 | I3: =(E3-G3)*100 -> 87.23
A4: 44566 | B4: 3.1051 | C4: 3.5307 | D4: 3.8183 | E4: 3.9533 | F4: 3.0049 | G4: 3.0837 | H4: =(D4-F4)*100 -> 81.34 | I4: =(E4-G4)*100 -> 86.96
A5: 44567 | B5: 3.1162 | C5: 3.5298 | D5: 3.8174 | E5: 3.9524 | F5: 3.0273 | G5: 3.0938 | H5: =(D5-F5)*100 -> 79.01 | I5: =(E5-G5)*100 -> 85.86
A6: 44568 | B6: 3.1177 | C6: 3.5318 | D6: 3.8194 | E6: 3.9544 | F6: 3.0373 | G6: 3.0966 | H6: =(D6-F6)*100 -> 78.21 | I6: =(E6-G6)*100 -> 85.78
A7: 44571 | B7: 3.0941 | C7: 3.5423 | D7: 3.8274 | E7: 3.9624 | F7: 3.0252 | G7: 3.0894 | H7: =(D7-F7)*100 -> 80.22 | I7: =(E7-G7)*100 -> 87.3
A8: 44572 | B8: 3.0803 | C8: 3.538 | D8: 3.8231 | E8: 3.9581 | F8: 3.022 | G8: 3.0845 | H8: =(D8-F8)*100 -> 80.11 | I8: =(E8-G8)*100 -> 87.36
A9: 44573 | B9: 3.0741 | C9: 3.53 | D9: 3.8236 | E9: 3.9586 | F9: 3.0256 | G9: 3.0894 | H9: =(D9-F9)*100 -> 79.8 | I9: =(E9-G9)*100 -> 86.92
A10: 44574 | B10: 3.0614 | C10: 3.5246 | D10: 3.8182 | E10: 3.9532 | F10: 3.0188 | G10: 3.0847 | H10: =(D10-F10)*100 -> 79.94 | I10: =(E10-G10)*100 -> 86.85
A11: 44575 | B11: 3.0651 | C11: 3.5204 | D11: 3.8037 | E11: 3.9387 | F11: 3.0248 | G11: 3.088 | H11: =(D11-F11)*100 -> 77.89 | I11: =(E11-G11)*100 -> 85.07
A12: 44578 | B12: 3.0513 | C12: 3.513 | D12: 3.7926 | E12: 3.9238 | F12: 3.0202 | G12: 3.0857 | H12: =(D12-F12)*100 -> 77.24 | I12: =(E12-G12)*100 -> 83.81
A13: 44579 | B13: 3.0326 | C13: 3.4974 | D13: 3.777 | E13: 3.9038 | F13: 2.9769 | G13: 3.03 | H13: =(D13-F13)*100 -> 80.01 | I13: =(E13-G13)*100 -> 87.38
A14: 44580 | B14: 2.9981 | C14: 3.4446 | D14: 3.7242 | E14: 3.851 | F14: 2.9494 | G14: 2.98 | H14: =(D14-F14)*100 -> 77.48 | I14: =(E14-G14)*100 -> 87.1
... A1200: 46318 | B1200: 1.6069 | C1200: 1.6941 | D1200: 1.8137 | E1200: 2.0463 | F1200: 1.5802 | G1200: 1.6741 | H1200: =(D1200-F1200)*100 -> 23.35 | I1200: =(E1200-G1200)*100 -> 37.22

Sheet RRG趋势计算
A1: RRG趋势计算 - 状态矩阵信号系统
A2: 日期 | B2: 比值 | C2: 比值42日MA | D2: X轴(相对强度%) | E2: X轴21日MA | F2: 趋势方向 | G2: Y轴(动量%)—14D | H2: 四象限 | I2: 价格区间 | J2: 趋势×价格
A3: =财富指数—趋势!A3 -> 44565 | B3: =财富指数—趋势!I3/财富指数—趋势!H3 -> 1.1230879
A4: =财富指数—趋势!A4 -> 44566 | B4: =财富指数—趋势!I4/财富指数—趋势!H4 -> 1.1230159
A5: =财富指数—趋势!A5 -> 44567 | B5: =财富指数—趋势!I5/财富指数—趋势!H5 -> 1.123209
A6: =财富指数—趋势!A6 -> 44568 | B6: =财富指数—趋势!I6/财富指数—趋势!H6 -> 1.1229324
A7: =财富指数—趋势!A7 -> 44571 | B7: =财富指数—趋势!I7/财富指数—趋势!H7 -> 1.1228651
A8: =财富指数—趋势!A8 -> 44572 | B8: =财富指数—趋势!I8/财富指数—趋势!H8 -> 1.1231204
A9: =财富指数—趋势!A9 -> 44573 | B9: =财富指数—趋势!I9/财富指数—趋势!H9 -> 1.1233557
A10: =财富指数—趋势!A10 -> 44574 | B10: =财富指数—趋势!I10/财富指数—趋势!H10 -> 1.1234726
A11: =财富指数—趋势!A11 -> 44575 | B11: =财富指数—趋势!I11/财富指数—趋势!H11 -> 1.1237579
A12: =财富指数—趋势!A12 -> 44578 | B12: =财富指数—趋势!I12/财富指数—趋势!H12 -> 1.123289
A13: =财富指数—趋势!A13 -> 44579 | B13: =财富指数—趋势!I13/财富指数—趋势!H13 -> 1.1233314
A14: =财富指数—趋势!A14 -> 44580 | B14: =财富指数—趋势!I14/财富指数—趋势!H14 -> 1.1240656
... A43: =财富指数—趋势!A43 -> 44624 | B43: =财富指数—趋势!I43/财富指数—趋势!H43 -> 1.1208929
A44: =财富指数—趋势!A44 -> 44627 | B44: =财富指数—趋势!I44/财富指数—趋势!H44 -> 1.1204564 | C44: =AVERAGE(B3:B44) -> 1.1230236 | D44: =(B44/C44-1)*100 -> -0.22860079
A45: =财富指数—趋势!A45 -> 44628 | B45: =财富指数—趋势!I45/财富指数—趋势!H45 -> 1.1204233 | C45: =AVERAGE(B4:B45) -> 1.1229602 | D45: =(B45/C45-1)*100 -> -0.22591285
A46: =财富指数—趋势!A46 -> 44629 | B46: =财富指数—趋势!I46/财富指数—趋势!H46 -> 1.119983 | C46: =AVERAGE(B5:B46) -> 1.122888 | D46: =(B46/C46-1)*100 -> -0.25870566
A47: =财富指数—趋势!A47 -> 44630 | B47: =财富指数—趋势!I47/财富指数—趋势!H47 -> 1.1193251 | C47: =AVERAGE(B6:B47) -> 1.1227955 | D47: =(B47/C47-1)*100 -> -0.30908831
A48: =财富指数—趋势!A48 -> 44631 | B48: =财富指数—趋势!I48/财富指数—趋势!H48 -> 1.1189999 | C48: =AVERAGE(B7:B48) -> 1.1227019 | D48: =(B48/C48-1)*100 -> -0.3297409
A49: =财富指数—趋势!A49 -> 44634 | B49: =财富指数—趋势!I49/财富指数—趋势!H49 -> 1.1193833 | C49: =AVERAGE(B8:B49) -> 1.122619 | D49: =(B49/C49-1)*100 -> -0.28822728
A50: =财富指数—趋势!A50 -> 44635 | B50: =财富指数—趋势!I50/财富指数—趋势!H50 -> 1.1192004 | C50: =AVERAGE(B9:B50) -> 1.1225256 | D50: =(B50/C50-1)*100 -> -0.29622431
A51: =财富指数—趋势!A51 -> 44636 | B51: =财富指数—趋势!I51/财富指数—趋势!H51 -> 1.1186653 | C51: =AVERAGE(B10:B51) -> 1.122414 | D51: =(B51/C51-1)*100 -> -0.3339787
A52: =财富指数—趋势!A52 -> 44637 | B52: =财富指数—趋势!I52/财富指数—趋势!H52 -> 1.1185581 | C52: =AVERAGE(B11:B52) -> 1.122297 | D52: =(B52/C52-1)*100 -> -0.33314152
A53: =财富指数—趋势!A53 -> 44638 | B53: =财富指数—趋势!I53/财富指数—趋势!H53 -> 1.1190017 | C53: =AVERAGE(B12:B53) -> 1.1221837 | D53: =(B53/C53-1)*100 -> -0.28355732
A54: =财富指数—趋势!A54 -> 44641 | B54: =财富指数—趋势!I54/财富指数—趋势!H54 -> 1.1185218 | C54: =AVERAGE(B13:B54) -> 1.1220702 | D54: =(B54/C54-1)*100 -> -0.31623871
A55: =财富指数—趋势!A55 -> 44642 | B55: =财富指数—趋势!I55/财富指数—趋势!H55 -> 1.1180852 | C55: =AVERAGE(B14:B55) -> 1.1219453 | D55: =(B55/C55-1)*100 -> -0.34405741
A56: =财富指数—趋势!A56 -> 44643 | B56: =财富指数—趋势!I56/财富指数—趋势!H56 -> 1.1178756 | C56: =AVERAGE(B15:B56) -> 1.1217979 | D56: =(B56/C56-1)*100 -> -0.34964761
A57: =财富指数—趋势!A57 -> 44644 | B57: =财富指数—趋势!I57/财富指数—趋势!H57 -> 1.1177063 | C57: =AVERAGE(B16:B57) -> 1.1216452 | D57: =(B57/C57-1)*100 -> -0.35116954 | G57: =D57-D44 -> -0.12256875
A58: =财富指数—趋势!A58 -> 44645 | B58: =财富指数—趋势!I58/财富指数—趋势!H58 -> 1.1174241 | C58: =AVERAGE(B17:B58) -> 1.1214823 | D58: =(B58/C58-1)*100 -> -0.36186546 | G58: =D58-D45 -> -0.13595261
A59: =财富指数—趋势!A59 -> 44648 | B59: =财富指数—趋势!I59/财富指数—趋势!H59 -> 1.1175123 | C59: =AVERAGE(B18:B59) -> 1.1213197 | D59: =(B59/C59-1)*100 -> -0.3395499 | G59: =D59-D46 -> -0.080844237
A60: =财富指数—趋势!A60 -> 44649 | B60: =财富指数—趋势!I60/财富指数—趋势!H60 -> 1.1173841 | C60: =AVERAGE(B19:B60) -> 1.1211526 | D60: =(B60/C60-1)*100 -> -0.3361288 | G60: =D60-D47 -> -0.027040485
A61: =财富指数—趋势!A61 -> 44650 | B61: =财富指数—趋势!I61/财富指数—趋势!H61 -> 1.1176013 | C61: =AVERAGE(B20:B61) -> 1.120988 | D61: =(B61/C61-1)*100 -> -0.30211781 | G61: =D61-D48 -> 0.027623091
A62: =财富指数—趋势!A62 -> 44651 | B62: =财富指数—趋势!I62/财富指数—趋势!H62 -> 1.1180512 | C62: =AVERAGE(B21:B62) -> 1.1208542 | D62: =(B62/C62-1)*100 -> -0.25008223 | G62: =D62-D49 -> 0.038145048
A63: =财富指数—趋势!A63 -> 44652 | B63: =财富指数—趋势!I63/财富指数—趋势!H63 -> 1.1184583 | C63: =AVERAGE(B22:B63) -> 1.1207271 | D63: =(B63/C63-1)*100 -> -0.2024419 | G63: =D63-D50 -> 0.093782416
A64: =财富指数—趋势!A64 -> 44653 | B64: =财富指数—趋势!I64/财富指数—趋势!H64 -> 1.1184399 | C64: =AVERAGE(B23:B64) -> 1.1205918 | D64: =(B64/C64-1)*100 -> -0.19203087 | E64: =AVERAGE(D44:D64) -> -0.29678609 | F64: =IF(E64>0,"上升","下降") -> 下降 | G64: =D64-D51 -> 0.14194784 | H64: =IF(AND(D64>0,G64>0),"领先",IF(AND(D64<=0,G64>0),"改善",IF(AND(D64>0,G64<=0),"减弱","滞后"))) -> 改善
A65: =财富指数—趋势!A65 -> 44657 | B65: =财富指数—趋势!I65/财富指数—趋势!H65 -> 1.1187192 | C65: =AVERAGE(B24:B65) -> 1.1204533 | D65: =(B65/C65-1)*100 -> -0.15477074 | E65: =AVERAGE(D45:D65) -> -0.29327037 | F65: =IF(E65>0,"上升","下降") -> 下降 | G65: =D65-D52 -> 0.17837078 | H65: =IF(AND(D65>0,G65>0),"领先",IF(AND(D65<=0,G65>0),"改善",IF(AND(D65>0,G65<=0),"减弱","滞后"))) -> 改善
A66: =财富指数—趋势!A66 -> 44658 | B66: =财富指数—趋势!I66/财富指数—趋势!H66 -> 1.1195069 | C66: =AVERAGE(B25:B66) -> 1.1203297 | D66: =(B66/C66-1)*100 -> -0.073438733 | E66: =AVERAGE(D46:D66) -> -0.2860097 | F66: =IF(E66>0,"上升","下降") -> 下降 | G66: =D66-D53 -> 0.21011859 | H66: =IF(AND(D66>0,G66>0),"领先",IF(AND(D66<=0,G66>0),"改善",IF(AND(D66>0,G66<=0),"减弱","滞后"))) -> 改善
A67: =财富指数—趋势!A67 -> 44659 | B67: =财富指数—趋势!I67/财富指数—趋势!H67 -> 1.1200711 | C67: =AVERAGE(B26:B67) -> 1.1202292 | D67: =(B67/C67-1)*100 -> -0.014111369 | E67: =AVERAGE(D47:D67) -> -0.27436235 | F67: =IF(E67>0,"上升","下降") -> 下降 | G67: =D67-D54 -> 0.30212734 | H67: =IF(AND(D67>0,G67>0),"领先",IF(AND(D67<=0,G67>0),"改善",IF(AND(D67>0,G67<=0),"减弱","滞后"))) -> 改善
A68: =财富指数—趋势!A68 -> 44662 | B68: =财富指数—趋势!I68/财富指数—趋势!H68 -> 1.1199406 | C68: =AVERAGE(B27:B68) -> 1.1201206 | D68: =(B68/C68-1)*100 -> -0.016069909 | E68: =AVERAGE(D48:D68) -> -0.2604091 | F68: =IF(E68>0,"上升","下降") -> 下降 | G68: =D68-D55 -> 0.3279875 | H68: =IF(AND(D68>0,G68>0),"领先",IF(AND(D68<=0,G68>0),"改善",IF(AND(D68>0,G68<=0),"减弱","滞后"))) -> 改善
...

Sheet 价格指标计算
A1: 价格指标计算 - 布林带 + PERCENTRANK分位数 (基于7Y收益率+7Y信用利差)
A2: 综合分位数=(收益率分位数+利差分位数)/2 | 价格区间:便宜>=55% 中性15~55% 贵<15% | 7Y是主交易期限,10Y供参考
A3: 日期 | B3: 7Y收益率 | C3: 60日MA | D3: 60日STD | E3: 上轨 | F3: 下轨 | G3: 收益率布林带位置% | H3: 7Y信用利差 | I3: 利差60日MA | J3: 利差60日STD | K3: 利差上轨 | L3: 利差下轨 | M3: 利差布林带位置% | N3: 布林带平均位置% | O3: 收益率分位数% | P3: 利差分位数% | Q3: 综合分位数% | R3: 价格区间
A4: =信用曲线—价格!A3 -> 44565 | B4: =信用曲线—价格!D3 -> 3.8168 | H4: =信用曲线—价格!H3 -> 82.47
A5: =信用曲线—价格!A4 -> 44566 | B5: =信用曲线—价格!D4 -> 3.8183 | H5: =信用曲线—价格!H4 -> 81.34
A6: =信用曲线—价格!A5 -> 44567 | B6: =信用曲线—价格!D5 -> 3.8174 | H6: =信用曲线—价格!H5 -> 79.01
A7: =信用曲线—价格!A6 -> 44568 | B7: =信用曲线—价格!D6 -> 3.8194 | H7: =信用曲线—价格!H6 -> 78.21
A8: =信用曲线—价格!A7 -> 44571 | B8: =信用曲线—价格!D7 -> 3.8274 | H8: =信用曲线—价格!H7 -> 80.22
A9: =信用曲线—价格!A8 -> 44572 | B9: =信用曲线—价格!D8 -> 3.8231 | H9: =信用曲线—价格!H8 -> 80.11
A10: =信用曲线—价格!A9 -> 44573 | B10: =信用曲线—价格!D9 -> 3.8236 | H10: =信用曲线—价格!H9 -> 79.8
A11: =信用曲线—价格!A10 -> 44574 | B11: =信用曲线—价格!D10 -> 3.8182 | H11: =信用曲线—价格!H10 -> 79.94
A12: =信用曲线—价格!A11 -> 44575 | B12: =信用曲线—价格!D11 -> 3.8037 | H12: =信用曲线—价格!H11 -> 77.89
A13: =信用曲线—价格!A12 -> 44578 | B13: =信用曲线—价格!D12 -> 3.7926 | H13: =信用曲线—价格!H12 -> 77.24
A14: =信用曲线—价格!A13 -> 44579 | B14: =信用曲线—价格!D13 -> 3.777 | H14: =信用曲线—价格!H13 -> 80.01
A15: =信用曲线—价格!A14 -> 44580 | B15: =信用曲线—价格!D14 -> 3.7242 | H15: =信用曲线—价格!H14 -> 77.48
... A62: =信用曲线—价格!A61 -> 44650 | B62: =信用曲线—价格!D61 -> 3.8902 | H62: =信用曲线—价格!H61 -> 84.34
A63: =信用曲线—价格!A62 -> 44651 | B63: =信用曲线—价格!D62 -> 3.8888 | C63: =AVERAGE(B4:B63) -> 3.809045 | D63: =STDEV(B4:B63) -> 0.075803594 | E63: =C63+2*D63 -> 3.9606522 | F63: =C63-2*D63 -> 3.6574378 | G63: =IF(AND(E63<>F63,NOT(ISBLANK(B63))),100*(B63-F63)/(E63-F63),"") -> 76.303172 | H63: =信用曲线—价格!H62 -> 84.18 | I63: =AVERAGE(H4:H63) -> 79.045667 | J63: =STDEV(H4:H63) -> 4.174443 | K63: =I63+2*J63 -> 87.394553 | L63: =I63-2*J63 -> 70.696781 | M63: =IF(AND(K63<>L63,NOT(ISBLANK(H63))),100*(H63-L63)/(K63-L63),"") -> 80.748613 | N63: =IF(AND(NOT(ISBLANK(G63)),NOT(ISBLANK(M63))),(G63+M63)/2,"") -> 78.525893
A64: =信用曲线—价格!A63 -> 44652 | B64: =信用曲线—价格!D63 -> 3.8802 | C64: =AVERAGE(B5:B64) -> 3.8101017 | D64: =STDEV(B5:B64) -> 0.076353417 | E64: =C64+2*D64 -> 3.9628085 | F64: =C64-2*D64 -> 3.6573948 | G64: =IF(AND(E64<>F64,NOT(ISBLANK(B64))),100*(B64-F64)/(E64-F64),"") -> 72.951931 | H64: =信用曲线—价格!H63 -> 85.89 | I64: =AVERAGE(H5:H64) -> 79.102667 | J64: =STDEV(H5:H64) -> 4.2447502 | K64: =I64+2*J64 -> 87.592167 | L64: =I64-2*J64 -> 70.613166 | M64: =IF(AND(K64<>L64,NOT(ISBLANK(H64))),100*(H64-L64)/(K64-L64),"") -> 89.974869 | N64: =IF(AND(NOT(ISBLANK(G64)),NOT(ISBLANK(M64))),(G64+M64)/2,"") -> 81.4634
A65: =信用曲线—价格!A64 -> 44653 | B65: =信用曲线—价格!D64 -> 3.8802 | C65: =AVERAGE(B6:B65) -> 3.8111333 | D65: =STDEV(B6:B65) -> 0.076882423 | E65: =C65+2*D65 -> 3.9648982 | F65: =C65-2*D65 -> 3.6573685 | G65: =IF(AND(E65<>F65,NOT(ISBLANK(B65))),100*(B65-F65)/(E65-F65),"") -> 72.458536 | H65: =信用曲线—价格!H64 -> 85.72 | I65: =AVERAGE(H6:H65) -> 79.175667 | J65: =STDEV(H6:H65) -> 4.3208601 | K65: =I65+2*J65 -> 87.817387 | L65: =I65-2*J65 -> 70.533947 | M65: =IF(AND(K65<>L65,NOT(ISBLANK(H65))),100*(H65-L65)/(K65-L65),"") -> 87.864761 | N65: =IF(AND(NOT(ISBLANK(G65)),NOT(ISBLANK(M65))),(G65+M65)/2,"") -> 80.161648
A66: =信用曲线—价格!A65 -> 44657 | B66: =信用曲线—价格!D65 -> 3.8744 | C66: =AVERAGE(B7:B66) -> 3.8120833 | D66: =STDEV(B7:B66) -> 0.07731213 | E66: =C66+2*D66 -> 3.9667076 | F66: =C66-2*D66 -> 3.6574591 | G66: =IF(AND(E66<>F66,NOT(ISBLANK(B66))),100*(B66-F66)/(E66-F66),"") -> 70.150999 | H66: =信用曲线—价格!H65 -> 84.51 | I66: =AVERAGE(H7:H66) -> 79.267333 | J66: =STDEV(H7:H66) -> 4.3752842 | K66: =I66+2*J66 -> 88.017902 | L66: =I66-2*J66 -> 70.516765 | M66: =IF(AND(K66<>L66,NOT(ISBLANK(H66))),100*(H66-L66)/(K66-L66),"") -> 79.95615 | N66: =IF(AND(NOT(ISBLANK(G66)),NOT(ISBLANK(M66))),(G66+M66)/2,"") -> 75.053574
A67: =信用曲线—价格!A66 -> 44658 | B67: =信用曲线—价格!D66 -> 3.862 | C67: =AVERAGE(B8:B67) -> 3.8127933 | D67: =STDEV(B8:B67) -> 0.077575623 | E67: =C67+2*D67 -> 3.9679446 | F67: =C67-2*D67 -> 3.6576421 | G67: =IF(AND(E67<>F67,NOT(ISBLANK(B67))),100*(B67-F67)/(E67-F67),"") -> 65.857645 | H67: =信用曲线—价格!H66 -> 85.22 | I67: =AVERAGE(H8:H67) -> 79.384167 | J67: =STDEV(H8:H67) -> 4.4396917 | K67: =I67+2*J67 -> 88.26355 | L67: =I67-2*J67 -> 70.504783 | M67: =IF(AND(K67<>L67,NOT(ISBLANK(H67))),100*(H67-L67)/(K67-L67),"") -> 82.861704 | N67: =IF(AND(NOT(ISBLANK(G67)),NOT(ISBLANK(M67))),(G67+M67)/2,"") -> 74.359674
A68: =信用曲线—价格!A67 -> 44659 | B68: =信用曲线—价格!D67 -> 3.8459 | C68: =AVERAGE(B9:B68) -> 3.8131017 | D68: =STDEV(B9:B68) -> 0.077671369 | E68: =C68+2*D68 -> 3.9684444 | F68: =C68-2*D68 -> 3.6577589 | G68: =IF(AND(E68<>F68,NOT(ISBLANK(B68))),100*(B68-F68)/(E68-F68),"") -> 60.556764 | H68: =信用曲线—价格!H67 -> 81.25 | I68: =AVERAGE(H9:H68) -> 79.401333 | J68: =STDEV(H9:H68) -> 4.4449665 | K68: =I68+2*J68 -> 88.291266 | L68: =I68-2*J68 -> 70.5114 | M68: =IF(AND(K68<>L68,NOT(ISBLANK(H68))),100*(H68-L68)/(K68-L68),"") -> 60.397529 | N68: =IF(AND(NOT(ISBLANK(G68)),NOT(ISBLANK(M68))),(G68+M68)/2,"") -> 60.477147
A69: =信用曲线—价格!A68 -> 44662 | B69: =信用曲线—价格!D68 -> 3.8428 | C69: =AVERAGE(B10:B69) -> 3.81343 | D69: =STDEV(B10:B69) -> 0.077755942 | E69: =C69+2*D69 -> 3.9689419 | F69: =C69-2*D69 -> 3.6579181 | G69: =IF(AND(E69<>F69,NOT(ISBLANK(B69))),100*(B69-F69)/(E69-F69),"") -> 59.443008 | H69: =信用曲线—价格!H68 -> 79.52 | I69: =AVERAGE(H10:H69) -> 79.3915 | J69: =STDEV(H10:H69) -> 4.4440247 | K69: =I69+2*J69 -> 88.279549 | L69: =I69-2*J69 -> 70.503451 | M69: =IF(AND(K69<>L69,NOT(ISBLANK(H69))),100*(H69-L69)/(K69-L69),"") -> 50.722881 | N69: =IF(AND(NOT(ISBLANK(G69)),NOT(ISBLANK(M69))),(G69+M69)/2,"") -> 55.082944
A70: =信用曲线—价格!A69 -> 44663 | B70: =信用曲线—价格!D69 -> 3.8375 | C70: =AVERAGE(B11:B70) -> 3.8136617 | D70: =STDEV(B11:B70) -> 0.077807446 | E70: =C70+2*D70 -> 3.9692766 | F70: =C70-2*D70 -> 3.6580468 | G70: =IF(AND(E70<>F70,NOT(ISBLANK(B70))),100*(B70-F70)/(E70-F70),"") -> 57.6594 | H70: =信用曲线—价格!H69 -> 79.22 | I70: =AVERAGE(H11:H70) -> 79.381833 | J70: =STDEV(H11:H70) -> 4.4437518 | K70: =I70+2*J70 -> 88.269337 | L70: =I70-2*J70 -> 70.49433 | M70: =IF(AND(K70<>L70,NOT(ISBLANK(H70))),100*(H70-L70)/(K70-L70),"") -> 49.089546 | N70: =IF(AND(NOT(ISBLANK(G70)),NOT(ISBLANK(M70))),(G70+M70)/2,"") -> 53.374473
A71: =信用曲线—价格!A70 -> 44664 | B71: =信用曲线—价格!D70 -> 3.8246 | C71: =AVERAGE(B12:B71) -> 3.8137683 | D71: =STDEV(B12:B71) -> 0.077818159 | E71: =C71+2*D71 -> 3.9694047 | F71: =C71-2*D71 -> 3.658132 | G71: =IF(AND(E71<>F71,NOT(ISBLANK(B71))),100*(B71-F71)/(E71-F71),"") -> 53.4798 | H71: =信用曲线—价格!H70 -> 79.02 | I71: =AVERAGE(H12:H71) -> 79.3665 | J71: =STDEV(H12:H71) -> 4.4433805 | K71: =I71+2*J71 -> 88.253261 | L71: =I71-2*J71 -> 70.479739 | M71: =IF(AND(K71<>L71,NOT(ISBLANK(H71))),100*(H71-L71)/(K71-L71),"") -> 48.050471 | N71: =IF(AND(NOT(ISBLANK(G71)),NOT(ISBLANK(M71))),(G71+M71)/2,"") -> 50.765136
A72: =信用曲线—价格!A71 -> 44665 | B72: =信用曲线—价格!D71 -> 3.8125 | C72: =AVERAGE(B13:B72) -> 3.813915 | D72: =STDEV(B13:B72) -> 0.077807154 | E72: =C72+2*D72 -> 3.9695293 | F72: =C72-2*D72 -> 3.6583007 | G72: =IF(AND(E72<>F72,NOT(ISBLANK(B72))),100*(B72-F72)/(E72-F72),"") -> 49.54535 | H72: =信用曲线—价格!H71 -> 79.72 | I72: =AVERAGE(H13:H72) -> 79.397 | J72: =STDEV(H13:H72) -> 4.4393526 | K72: =I72+2*J72 -> 88.275705 | L72: =I72-2*J72 -> 70.518295 | M72: =IF(AND(K72<>L72,NOT(ISBLANK(H72))),100*(H72-L72)/(K72-L72),"") -> 51.818959 | N72: =IF(AND(NOT(ISBLANK(G72)),NOT(ISBLANK(M72))),(G72+M72)/2,"") -> 50.682155
A73: =信用曲线—价格!A72 -> 44666 | B73: =信用曲线—价格!D72 -> 3.8111 | C73: =AVERAGE(B14:B73) -> 3.8142233 | D73: =STDEV(B14:B73) -> 0.077757895 | E73: =C73+2*D73 -> 3.9697391 | F73: =C73-2*D73 -> 3.6587075 | G73: =IF(AND(E73<>F73,NOT(ISBLANK(B73))),100*(B73-F73)/(E73-F73),"") -> 48.995815 | H73: =信用曲线—价格!H72 -> 80.5 | I73: =AVERAGE(H14:H73) -> 79.451333 | J73: =STDEV(H14:H73) -> 4.4324499 | K73: =I73+2*J73 -> 88.316233 | L73: =I73-2*J73 -> 70.586434 | M73: =IF(AND(K73<>L73,NOT(ISBLANK(H73))),100*(H73-L73)/(K73-L73),"") -> 55.914713 | N73: =IF(AND(NOT(ISBLANK(G73)),NOT(ISBLANK(M73))),(G73+M73)/2,"") -> 52.455264
A74: =信用曲线—价格!A73 -> 44669 | B74: =信用曲线—价格!D73 -> 3.811 | C74: =AVERAGE(B15:B74) -> 3.81479 | D74: =STDEV(B15:B74) -> 0.07760577 | E74: =C74+2*D74 -> 3.9700015 | F74: =C74-2*D74 -> 3.6595785 | G74: =IF(AND(E74<>F74,NOT(ISBLANK(B74))),100*(B74-F74)/(E74-F74),"") -> 48.779086 | H74: =信用曲线—价格!H73 -> 76.43 | I74: =AVERAGE(H15:H74) -> 79.391667 | J74: =STDEV(H15:H74) -> 4.4488674 | K74: =I74+2*J74 -> 88.289401 | L74: =I74-2*J74 -> 70.493932 | M74: =IF(AND(K74<>L74,NOT(ISBLANK(H74))),100*(H74-L74)/(K74-L74),"") -> 33.357187 | N74: =IF(AND(NOT(ISBLANK(G74)),NOT(ISBLANK(M74))),(G74+M74)/2,"") -> 41.068136
... A254: =信用曲线—价格!A253 -> 44929 | B254: =信用曲线—价格!D253 -> 3.9875 | C254: =AVERAGE(B195:B254) -> 3.685815 | D254: =STDEV(B195:B254) -> 0.22242851 | E254: =C254+2*D254 -> 4.130672 | F254: =C254-2*D254 -> 3.240958 | G254: =IF(AND(E254<>F254,NOT(ISBLANK(B254))),100*(B254-F254)/(E254-F254),"") -> 83.908086 | H254: =信用曲线—价格!H253 -> 99.9 | I254: =AVERAGE(H195:H254) -> 76.426 | J254: =STDEV(H195:H254) -> 15.690944 | K254: =I254+2*J254 -> 107.80789 | L254: =I254-2*J254 -> 45.044112 | M254: =IF(AND(K254<>L254,NOT(ISBLANK(H254))),100*(H254-L254)/(K254-L254),"") -> 87.400554 | N254: =IF(AND(NOT(ISBLANK(G254)),NOT(ISBLANK(M254))),(G254+M254)/2,"") -> 85.65432
A255: =信用曲线—价格!A254 -> 44930 | B255: =信用曲线—价格!D254 -> 3.9656 | C255: =AVERAGE(B196:B255) -> 3.6939667 | D255: =STDEV(B196:B255) -> 0.22358678 | E255: =C255+2*D255 -> 4.1411402 | F255: =C255-2*D255 -> 3.2467931 | G255: =IF(AND(E255<>F255,NOT(ISBLANK(B255))),100*(B255-F255)/(E255-F255),"") -> 80.372249 | H255: =信用曲线—价格!H254 -> 101.55 | I255: =AVERAGE(H196:H255) -> 77.1125 | J255: =STDEV(H196:H255) -> 15.876088 | K255: =I255+2*J255 -> 108.86468 | L255: =I255-2*J255 -> 45.360324 | M255: =IF(AND(K255<>L255,NOT(ISBLANK(H255))),100*(H255-L255)/(K255-L255),"") -> 88.481615 | N255: =IF(AND(NOT(ISBLANK(G255)),NOT(ISBLANK(M255))),(G255+M255)/2,"") -> 84.426932 | P255: =IFERROR(_xlfn.PERCENTRANK.EXC(INDEX(H:H, MAX(4, ROW()-251)):INDEX(H:H, ROW()), H255), "") -> 0.992 | Q255: =AVERAGE(O255:P255) -> 0.992 | R255: =IF(Q253="", "", IF(Q253>=55, "便宜", IF(Q253>=15, "中性", "贵")))
A256: =信用曲线—价格!A255 -> 44931 | B256: =信用曲线—价格!D255 -> 3.9455 | C256: =AVERAGE(B197:B256) -> 3.7016167 | D256: =STDEV(B197:B256) -> 0.22421944 | E256: =C256+2*D256 -> 4.1500556 | F256: =C256-2*D256 -> 3.2531778 | G256: =IF(AND(E256<>F256,NOT(ISBLANK(B256))),100*(B256-F256)/(E256-F256),"") -> 77.192483 | H256: =信用曲线—价格!H255 -> 98.94 | I256: =AVERAGE(H197:H256) -> 77.743 | J256: =STDEV(H197:H256) -> 15.980639 | K256: =I256+2*J256 -> 109.70428 | L256: =I256-2*J256 -> 45.781723 | M256: =IF(AND(K256<>L256,NOT(ISBLANK(H256))),100*(H256-L256)/(K256-L256),"") -> 83.160439 | N256: =IF(AND(NOT(ISBLANK(G256)),NOT(ISBLANK(M256))),(G256+M256)/2,"") -> 80.176461 | O256: =IFERROR(_xlfn.PERCENTRANK.EXC(INDEX(B:B, MAX(4, ROW()-251)):INDEX(B:B, ROW()), B256), "") -> 0.928 | P256: =IFERROR(_xlfn.PERCENTRANK.EXC(INDEX(H:H, MAX(4, ROW()-251)):INDEX(H:H, ROW()), H256), "") -> 0.932 | Q256: =AVERAGE(O256:P256) -> 0.93 | R256: =IF(Q254="", "", IF(Q254>=55, "便宜", IF(Q254>=15, "中性", "贵")))
A257: =信用曲线—价格!A256 -> 44932 | B257: =信用曲线—价格!D256 -> 3.9355 | C257: =AVERAGE(B198:B257) -> 3.7095067 | D257: =STDEV(B198:B257) -> 0.22397734 | E257: =C257+2*D257 -> 4.1574614 | F257: =C257-2*D257 -> 3.261552 | G257: =IF(AND(E257<>F257,NOT(ISBLANK(B257))),100*(B257-F257)/(E257-F257),"") -> 75.225022 | H257: =信用曲线—价格!H256 -> 96.82 | I257: =AVERAGE(H198:H257) -> 78.3645 | J257: =STDEV(H198:H257) -> 15.985433 | K257: =I257+2*J257 -> 110.33537 | L257: =I257-2*J257 -> 46.393633 | M257: =IF(AND(K257<>L257,NOT(ISBLANK(H257))),100*(H257-L257)/(K257-L257),"") -> 78.862996 | N257: =IF(AND(NOT(ISBLANK(G257)),NOT(ISBLANK(M257))),(G257+M257)/2,"") -> 77.044009 | O257: =IFERROR(_xlfn.PERCENTRANK.EXC(INDEX(B:B, MAX(4, ROW()-251)):INDEX(B:B, ROW()), B257), "") -> 0.924 | P257: =IFERROR(_xlfn.PERCENTRANK.EXC(INDEX(H:H, MAX(4, ROW()-251)):INDEX(H:H, ROW()), H257), "") -> 0.928 | Q257: =AVERAGE(O257:P257) -> 0.926 | R257: =IF(Q257="", "", IF(Q257>=0.55, "便宜", IF(Q257>=0.15, "中性", "贵"))) -> 便宜
A258: =信用曲线—价格!A257 -> 44935 | B258: =信用曲线—价格!D257 -> 3.9517 | C258: =AVERAGE(B199:B258) -> 3.71785 | D258: =STDEV(B199:B258) -> 0.22351173 | E258: =C258+2*D258 -> 4.1648735 | F258: =C258-2*D258 -> 3.2708265 | G258: =IF(AND(E258<>F258,NOT(ISBLANK(B258))),100*(B258-F258)/(E258-F258),"") -> 76.156345 | H258: =信用曲线—价格!H257 -> 98.16 | I258: =AVERAGE(H199:H258) -> 79.013167 | J258: =STDEV(H199:H258) -> 15.985894 | K258: =I258+2*J258 -> 110.98496 | L258: =I258-2*J258 -> 47.041378 | M258: =IF(AND(K258<>L258,NOT(ISBLANK(H258))),100*(H258-L258)/(K258-L258),"") -> 79.943325 | N258: =IF(AND(NOT(ISBLANK(G258)),NOT(ISBLANK(M258))),(G258+M258)/2,"") -> 78.049835 | O258: =IFERROR(_xlfn.PERCENTRANK.EXC(INDEX(B:B, MAX(4, ROW()-251)):INDEX(B:B, ROW()), B258), "") -> 0.928 | P258: =IFERROR(_xlfn.PERCENTRANK.EXC(INDEX(H:H, MAX(4, ROW()-251)):INDEX(H:H, ROW()), H258), "") -> 0.928 | Q258: =AVERAGE(O258:P258) -> 0.928 | R258: =IF(Q258="", "", IF(Q258>=0.55, "便宜", IF(Q258>=0.15, "中性", "贵"))) -> 便宜
A259: =信用曲线—价格!A258 -> 44936 | B259: =信用曲线—价格!D258 -> 3.9598 | C259: =AVERAGE(B200:B259) -> 3.7264433 | D259: =STDEV(B200:B259) -> 0.22272263 | E259: =C259+2*D259 -> 4.1718886 | F259: =C259-2*D259 -> 3.2809981 | G259: =IF(AND(E259<>F259,NOT(ISBLANK(B259))),100*(B259-F259)/(E259-F259),"") -> 76.193641 | H259: =信用曲线—价格!H258 -> 97.72 | I259: =AVERAGE(H200:H259) -> 79.646167 | J259: =STDEV(H200:H259) -> 15.961728 | K259: =I259+2*J259 -> 111.56962 | L259: =I259-2*J259 -> 47.72271 | M259: =IF(AND(K259<>L259,NOT(ISBLANK(H259))),100*(H259-L259)/(K259-L259),"") -> 78.308077 | N259: =IF(AND(NOT(ISBLANK(G259)),NOT(ISBLANK(M259))),(G259+M259)/2,"") -> 77.250859 | O259: =IFERROR(_xlfn.PERCENTRANK.EXC(INDEX(B:B, MAX(4, ROW()-251)):INDEX(B:B, ROW()), B259), "") -> 0.928 | P259: =IFERROR(_xlfn.PERCENTRANK.EXC(INDEX(H:H, MAX(4, ROW()-251)):INDEX(H:H, ROW()), H259), "") -> 0.924 | Q259: =AVERAGE(O259:P259) -> 0.926 | R259: =IF(Q259="", "", IF(Q259>=0.55, "便宜", IF(Q259>=0.15, "中性", "贵"))) -> 便宜
A260: =信用曲线—价格!A259 -> 44937 | B260: =信用曲线—价格!D259 -> 3.9648 | C260: =AVERAGE(B201:B260) -> 3.7352217 | D260: =STDEV(B201:B260) -> 0.2215418 | E260: =C260+2*D260 -> 4.1783053 | F260: =C260-2*D260 -> 3.2921381 | G260: =IF(AND(E260<>F260,NOT(ISBLANK(B260))),100*(B260-F260)/(E260-F260),"") -> 75.906887 | H260: =信用曲线—价格!H259 -> 97.22 | I260: =AVERAGE(H201:H260) -> 80.246333 | J260: =STDEV(H201:H260) -> 15.933742 | K260: =I260+2*J260 -> 112.11382 | L260: =I260-2*J260 -> 48.378848 | M260: =IF(AND(K260<>L260,NOT(ISBLANK(H260))),100*(H260-L260)/(K260-L260),"") -> 76.631638 | N260: =IF(AND(NOT(ISBLANK(G260)),NOT(ISBLANK(M260))),(G260+M260)/2,"") -> 76.269263 | O260: =IFERROR(_xlfn.PERCENTRANK.EXC(INDEX(B:B, MAX(4, ROW()-251)):INDEX(B:B, ROW()), B260), "") -> 0.928 | P260: =IFERROR(_xlfn.PERCENTRANK.EXC(INDEX(H:H, MAX(4, ROW()-251)):INDEX(H:H, ROW()), H260), "") -> 0.92 | Q260: =AVERAGE(O260:P260) -> 0.924 | R260: =IF(Q260="", "", IF(Q260>=0.55, "便宜", IF(Q260>=0.15, "中性", "贵"))) -> 便宜
A261: =信用曲线—价格!A260 -> 44938 | B261: =信用曲线—价格!D260 -> 3.9648 | C261: =AVERAGE(B202:B261) -> 3.744235 | D261: =STDEV(B202:B261) -> 0.21965837 | E261: =C261+2*D261 -> 4.1835517 | F261: =C261-2*D261 -> 3.3049183 | G261: =IF(AND(E261<>F261,NOT(ISBLANK(B261))),100*(B261-F261)/(E261-F261),"") -> 75.103186 | H261: =信用曲线—价格!H260 -> 97.33 | I261: =AVERAGE(H202:H261) -> 80.886833 | J261: =STDEV(H202:H261) -> 15.833207 | K261: =I261+2*J261 -> 112.55325 | L261: =I261-2*J261 -> 49.220419 | M261: =IF(AND(K261<>L261,NOT(ISBLANK(H261))),100*(H261-L261)/(K261-L261),"") -> 75.963102 | N261: =IF(AND(NOT(ISBLANK(G261)),NOT(ISBLANK(M261))),(G261+M261)/2,"") -> 75.533144 | O261: =IFERROR(_xlfn.PERCENTRANK.EXC(INDEX(B:B, MAX(4, ROW()-251)):INDEX(B:B, ROW()), B261), "") -> 0.924 | P261: =IFERROR(_xlfn.PERCENTRANK.EXC(INDEX(H:H, MAX(4, ROW()-251)):INDEX(H:H, ROW()), H261), "") -> 0.92 | Q261: =AVERAGE(O261:P261) -> 0.922 | R261: =IF(Q261="", "", IF(Q261>=0.55, "便宜", IF(Q261>=0.15, "中性", "贵"))) -> 便宜
A262: =信用曲线—价格!A261 -> 44939 | B262: =信用曲线—价格!D261 -> 3.9694 | C262: =AVERAGE(B203:B262) -> 3.7533433 | D262: =STDEV(B203:B262) -> 0.21742732 | E262: =C262+2*D262 -> 4.188198 | F262: =C262-2*D262 -> 3.3184887 | G262: =IF(AND(E262<>F262,NOT(ISBLANK(B262))),100*(B262-F262)/(E262-F262),"") -> 74.842401 | H262: =信用曲线—价格!H261 -> 96.54 | I262: =AVERAGE(H203:H262) -> 81.5185 | J262: =STDEV(H203:H262) -> 15.685952 | K262: =I262+2*J262 -> 112.8904 | L262: =I262-2*J262 -> 50.146596 | M262: =IF(AND(K262<>L262,NOT(ISBLANK(H262))),100*(H262-L262)/(K262-L262),"") -> 73.941008 | N262: =IF(AND(NOT(ISBLANK(G262)),NOT(ISBLANK(M262))),(G262+M262)/2,"") -> 74.391705 | O262: =IFERROR(_xlfn.PERCENTRANK.EXC(INDEX(B:B, MAX(4, ROW()-251)):INDEX(B:B, ROW()), B262), "") -> 0.932 | P262: =IFERROR(_xlfn.PERCENTRANK.EXC(INDEX(H:H, MAX(4, ROW()-251)):INDEX(H:H, ROW()), H262), "") -> 0.905 | Q262: =AVERAGE(O262:P262) -> 0.9185 | R262: =IF(Q262="", "", IF(Q262>=0.55, "便宜", IF(Q262>=0.15, "中性", "贵"))) -> 便宜
A263: =信用曲线—价格!A262 -> 44942 | B263: =信用曲线—价格!D262 -> 3.9945 | C263: =AVERAGE(B204:B263) -> 3.76287 | D263: =STDEV(B204:B263) -> 0.21521459 | E263: =C263+2*D263 -> 4.1932992 | F263: =C263-2*D263 -> 3.3324408 | G263: =IF(AND(E263<>F263,NOT(ISBLANK(B263))),100*(B263-F263)/(E263-F263),"") -> 76.906865 | H263: =信用曲线—价格!H262 -> 96.05 | I263: =AVERAGE(H204:H263) -> 82.124167 | J263: =STDEV(H204:H263) -> 15.530418 | K263: =I263+2*J263 -> 113.185 | L263: =I263-2*J263 -> 51.06333 | M263: =IF(AND(K263<>L263,NOT(ISBLANK(H263))),100*(H263-L263)/(K263-L263),"") -> 72.417029 | N263: =IF(AND(NOT(ISBLANK(G263)),NOT(ISBLANK(M263))),(G263+M263)/2,"") -> 74.661947 | O263: =IFERROR(_xlfn.PERCENTRANK.EXC(INDEX(B:B, MAX(4, ROW()-251)):INDEX(B:B, ROW()), B263), "") -> 0.972 | P263: =IFERROR(_xlfn.PERCENTRANK.EXC(INDEX(H:H, MAX(4, ROW()-251)):INDEX(H:H, ROW()), H263), "") -> 0.901 | Q263: =AVERAGE(O263:P263) -> 0.9365 | R263: =IF(Q263="", "", IF(Q263>=0.55, "便宜", IF(Q263>=0.15, "中性", "贵"))) -> 便宜
A264: =信用曲线—价格!A263 -> 44943 | B264: =信用曲线—价格!D263 -> 4.0045 | C264: =AVERAGE(B205:B264) -> 3.7725133 | D264: =STDEV(B205:B264) -> 0.21280924 | E264: =C264+2*D264 -> 4.1981318 | F264: =C264-2*D264 -> 3.3468949 | G264: =IF(AND(E264<>F264,NOT(ISBLANK(B264))),100*(B264-F264)/(E264-F264),"") -> 77.252889 | H264: =信用曲线—价格!H263 -> 96.98 | I264: =AVERAGE(H205:H264) -> 82.757167 | J264: =STDEV(H205:H264) -> 15.344831 | K264: =I264+2*J264 -> 113.44683 | L264: =I264-2*J264 -> 52.067504 | M264: =IF(AND(K264<>L264,NOT(ISBLANK(H264))),100*(H264-L264)/(K264-L264),"") -> 73.172026 | N264: =IF(AND(NOT(ISBLANK(G264)),NOT(ISBLANK(M264))),(G264+M264)/2,"") -> 75.212458 | O264: =IFERROR(_xlfn.PERCENTRANK.EXC(INDEX(B:B, MAX(4, ROW()-251)):INDEX(B:B, ROW()), B264), "") -> 0.988 | P264: =IFERROR(_xlfn.PERCENTRANK.EXC(INDEX(H:H, MAX(4, ROW()-251)):INDEX(H:H, ROW()), H264), "") -> 0.913 | Q264: =AVERAGE(O264:P264) -> 0.9505 | R264: =IF(Q264="", "", IF(Q264>=0.55, "便宜", IF(Q264>=0.15, "中性", "贵"))) -> 便宜
A265: =信用曲线—价格!A264 -> 44944 | B265: =信用曲线—价格!D264 -> 4.0145 | C265: =AVERAGE(B206:B265) -> 3.78234 | D265: =STDEV(B206:B265) -> 0.21008099 | E265: =C265+2*D265 -> 4.202502 | F265: =C265-2*D265 -> 3.362178 | G265: =IF(AND(E265<>F265,NOT(ISBLANK(B265))),100*(B265-F265)/(E265-F265),"") -> 77.62744 | H265: =信用曲线—价格!H264 -> 97.98 | I265: =AVERAGE(H206:H265) -> 83.391833 | J265: =STDEV(H206:H265) -> 15.169932 | K265: =I265+2*J265 -> 113.7317 | L265: =I265-2*J265 -> 53.051969 | M265: =IF(AND(K265<>L265,NOT(ISBLANK(H265))),100*(H265-L265)/(K265-L265),"") -> 74.041252 | N265: =IF(AND(NOT(ISBLANK(G265)),NOT(ISBLANK(M265))),(G265+M265)/2,"") -> 75.834346 | O265: =IFERROR(_xlfn.PERCENTRANK.EXC(INDEX(B:B, MAX(4, ROW()-251)):INDEX(B:B, ROW()), B265), "") -> 0.992 | P265: =IFERROR(_xlfn.PERCENTRANK.EXC(INDEX(H:H, MAX(4, ROW()-251)):INDEX(H:H, ROW()), H265), "") -> 0.924 | Q265: =AVERAGE(O265:P265) -> 0.958 | R265: =IF(Q265="", "", IF(Q265>=0.55, "便宜", IF(Q265>=0.15, "中性", "贵"))) -> 便宜
...

Sheet 信号判断
A1: 矩阵式信号判断 - 趋势象限 × 价格区间 × 趋势方向 → 操作信号
A2: 确认期:3天 | 趋势上升时趋势溢价均持仓 | 趋势下降时:减弱+贵→卖,减弱+中性→卖,改善+贵→卖,滞后→空仓,其余→持仓
A3: 日期 | B3: 四象限 | C3: 价格区间 | D3: 趋势方向 | E3: 矩阵信号 | F3: 信号原因 | G3: 确认后持仓 | H3: 交易动作 | I3: 7Y收益率% | J3: 综合分位数% | K3: X轴% | L3: Y轴%
A4: =RRG趋势计算!A3 -> 44565 | B4: =RRG趋势计算!H3 -> 0 | C4: =价格指标计算!R4 -> 0 | D4: =RRG趋势计算!F3 -> 0 | E4: =IF(OR(B4="",C4="",D4=""),"",IF(D4="上升","持仓",IF(AND(B4="减弱",C4="贵"),"空仓",IF(AND(B4="减弱",C4="中性"),"空仓",IF(AND(B4="改善",C4="贵"),"空仓",IF(B4="滞后","空仓","持仓")))))) -> 持仓 | F4: =IF(OR(B4="",C4="",D4=""),"",IF(D4="上升","趋势上升,趋势溢价持有",IF(AND(B4="减弱",C4="贵"),"趋势减弱+价格贵+下降,卖出",IF(AND(B4="减弱",C4="中性"),"趋势减弱+中性+下降,卖出预警",IF(AND(B4="改善",C4="贵"),"趋势改善+贵+下降,卖出",IF(B4="滞后","趋势滞后+下降,空仓","趋势尚可+下降,持有")))))) -> 趋势尚可+下降,持有 | G4: =E4 -> 持仓 | I4: =价格指标计算!B4 -> 3.8168
A5: =RRG趋势计算!A4 -> 44566 | B5: =RRG趋势计算!H4 -> 0 | C5: =价格指标计算!R5 -> 0 | D5: =RRG趋势计算!F4 -> 0 | E5: =IF(OR(B5="",C5="",D5=""),"",IF(D5="上升","持仓",IF(AND(B5="减弱",C5="贵"),"空仓",IF(AND(B5="减弱",C5="中性"),"空仓",IF(AND(B5="改善",C5="贵"),"空仓",IF(B5="滞后","空仓","持仓")))))) -> 持仓 | F5: =IF(OR(B5="",C5="",D5=""),"",IF(D5="上升","趋势上升,趋势溢价持有",IF(AND(B5="减弱",C5="贵"),"趋势减弱+价格贵+下降,卖出",IF(AND(B5="减弱",C5="中性"),"趋势减弱+中性+下降,卖出预警",IF(AND(B5="改善",C5="贵"),"趋势改善+贵+下降,卖出",IF(B5="滞后","趋势滞后+下降,空仓","趋势尚可+下降,持有")))))) -> 趋势尚可+下降,持有 | G5: =E5 -> 持仓 | I5: =价格指标计算!B5 -> 3.8183
A6: =RRG趋势计算!A5 -> 44567 | B6: =RRG趋势计算!H5 -> 0 | C6: =价格指标计算!R6 -> 0 | D6: =RRG趋势计算!F5 -> 0 | E6: =IF(OR(B6="",C6="",D6=""),"",IF(D6="上升","持仓",IF(AND(B6="减弱",C6="贵"),"空仓",IF(AND(B6="减弱",C6="中性"),"空仓",IF(AND(B6="改善",C6="贵"),"空仓",IF(B6="滞后","空仓","持仓")))))) -> 持仓 | F6: =IF(OR(B6="",C6="",D6=""),"",IF(D6="上升","趋势上升,趋势溢价持有",IF(AND(B6="减弱",C6="贵"),"趋势减弱+价格贵+下降,卖出",IF(AND(B6="减弱",C6="中性"),"趋势减弱+中性+下降,卖出预警",IF(AND(B6="改善",C6="贵"),"趋势改善+贵+下降,卖出",IF(B6="滞后","趋势滞后+下降,空仓","趋势尚可+下降,持有")))))) -> 趋势尚可+下降,持有 | G6: =E6 -> 持仓 | I6: =价格指标计算!B6 -> 3.8174
A7: =RRG趋势计算!A6 -> 44568 | B7: =RRG趋势计算!H6 -> 0 | C7: =价格指标计算!R7 -> 0 | D7: =RRG趋势计算!F6 -> 0 | E7: =IF(OR(B7="",C7="",D7=""),"",IF(D7="上升","持仓",IF(AND(B7="减弱",C7="贵"),"空仓",IF(AND(B7="减弱",C7="中性"),"空仓",IF(AND(B7="改善",C7="贵"),"空仓",IF(B7="滞后","空仓","持仓")))))) -> 持仓 | F7: =IF(OR(B7="",C7="",D7=""),"",IF(D7="上升","趋势上升,趋势溢价持有",IF(AND(B7="减弱",C7="贵"),"趋势减弱+价格贵+下降,卖出",IF(AND(B7="减弱",C7="中性"),"趋势减弱+中性+下降,卖出预警",IF(AND(B7="改善",C7="贵"),"趋势改善+贵+下降,卖出",IF(B7="滞后","趋势滞后+下降,空仓","趋势尚可+下降,持有")))))) -> 趋势尚可+下降,持有 | G7: =E7 -> 持仓 | I7: =价格指标计算!B7 -> 3.8194
A8: =RRG趋势计算!A7 -> 44571 | B8: =RRG趋势计算!H7 -> 0 | C8: =价格指标计算!R8 -> 0 | D8: =RRG趋势计算!F7 -> 0 | E8: =IF(OR(B8="",C8="",D8=""),"",IF(D8="上升","持仓",IF(AND(B8="减弱",C8="贵"),"空仓",IF(AND(B8="减弱",C8="中性"),"空仓",IF(AND(B8="改善",C8="贵"),"空仓",IF(B8="滞后","空仓","持仓")))))) -> 持仓 | F8: =IF(OR(B8="",C8="",D8=""),"",IF(D8="上升","趋势上升,趋势溢价持有",IF(AND(B8="减弱",C8="贵"),"趋势减弱+价格贵+下降,卖出",IF(AND(B8="减弱",C8="中性"),"趋势减弱+中性+下降,卖出预警",IF(AND(B8="改善",C8="贵"),"趋势改善+贵+下降,卖出",IF(B8="滞后","趋势滞后+下降,空仓","趋势尚可+下降,持有")))))) -> 趋势尚可+下降,持有 | G8: =E8 -> 持仓 | I8: =价格指标计算!B8 -> 3.8274
A9: =RRG趋势计算!A8 -> 44572 | B9: =RRG趋势计算!H8 -> 0 | C9: =价格指标计算!R9 -> 0 | D9: =RRG趋势计算!F8 -> 0 | E9: =IF(OR(B9="",C9="",D9=""),"",IF(D9="上升","持仓",IF(AND(B9="减弱",C9="贵"),"空仓",IF(AND(B9="减弱",C9="中性"),"空仓",IF(AND(B9="改善",C9="贵"),"空仓",IF(B9="滞后","空仓","持仓")))))) -> 持仓 | F9: =IF(OR(B9="",C9="",D9=""),"",IF(D9="上升","趋势上升,趋势溢价持有",IF(AND(B9="减弱",C9="贵"),"趋势减弱+价格贵+下降,卖出",IF(AND(B9="减弱",C9="中性"),"趋势减弱+中性+下降,卖出预警",IF(AND(B9="改善",C9="贵"),"趋势改善+贵+下降,卖出",IF(B9="滞后","趋势滞后+下降,空仓","趋势尚可+下降,持有")))))) -> 趋势尚可+下降,持有 | G9: =E9 -> 持仓 | I9: =价格指标计算!B9 -> 3.8231
A10: =RRG趋势计算!A9 -> 44573 | B10: =RRG趋势计算!H9 -> 0 | C10: =价格指标计算!R10 -> 0 | D10: =RRG趋势计算!F9 -> 0 | E10: =IF(OR(B10="",C10="",D10=""),"",IF(D10="上升","持仓",IF(AND(B10="减弱",C10="贵"),"空仓",IF(AND(B10="减弱",C10="中性"),"空仓",IF(AND(B10="改善",C10="贵"),"空仓",IF(B10="滞后","空仓","持仓")))))) -> 持仓 | F10: =IF(OR(B10="",C10="",D10=""),"",IF(D10="上升","趋势上升,趋势溢价持有",IF(AND(B10="减弱",C10="贵"),"趋势减弱+价格贵+下降,卖出",IF(AND(B10="减弱",C10="中性"),"趋势减弱+中性+下降,卖出预警",IF(AND(B10="改善",C10="贵"),"趋势改善+贵+下降,卖出",IF(B10="滞后","趋势滞后+下降,空仓","趋势尚可+下降,持有")))))) -> 趋势尚可+下降,持有 | G10: =E10 -> 持仓 | I10: =价格指标计算!B10 -> 3.8236
A11: =RRG趋势计算!A10 -> 44574 | B11: =RRG趋势计算!H10 -> 0 | C11: =价格指标计算!R11 -> 0 | D11: =RRG趋势计算!F10 -> 0 | E11: =IF(OR(B11="",C11="",D11=""),"",IF(D11="上升","持仓",IF(AND(B11="减弱",C11="贵"),"空仓",IF(AND(B11="减弱",C11="中性"),"空仓",IF(AND(B11="改善",C11="贵"),"空仓",IF(B11="滞后","空仓","持仓")))))) -> 持仓 | F11: =IF(OR(B11="",C11="",D11=""),"",IF(D11="上升","趋势上升,趋势溢价持有",IF(AND(B11="减弱",C11="贵"),"趋势减弱+价格贵+下降,卖出",IF(AND(B11="减弱",C11="中性"),"趋势减弱+中性+下降,卖出预警",IF(AND(B11="改善",C11="贵"),"趋势改善+贵+下降,卖出",IF(B11="滞后","趋势滞后+下降,空仓","趋势尚可+下降,持有")))))) -> 趋势尚可+下降,持有 | G11: =E11 -> 持仓 | I11: =价格指标计算!B11 -> 3.8182
A12: =RRG趋势计算!A11 -> 44575 | B12: =RRG趋势计算!H11 -> 0 | C12: =价格指标计算!R12 -> 0 | D12: =RRG趋势计算!F11 -> 0 | E12: =IF(OR(B12="",C12="",D12=""),"",IF(D12="上升","持仓",IF(AND(B12="减弱",C12="贵"),"空仓",IF(AND(B12="减弱",C12="中性"),"空仓",IF(AND(B12="改善",C12="贵"),"空仓",IF(B12="滞后","空仓","持仓")))))) -> 持仓 | F12: =IF(OR(B12="",C12="",D12=""),"",IF(D12="上升","趋势上升,趋势溢价持有",IF(AND(B12="减弱",C12="贵"),"趋势减弱+价格贵+下降,卖出",IF(AND(B12="减弱",C12="中性"),"趋势减弱+中性+下降,卖出预警",IF(AND(B12="改善",C12="贵"),"趋势改善+贵+下降,卖出",IF(B12="滞后","趋势滞后+下降,空仓","趋势尚可+下降,持有")))))) -> 趋势尚可+下降,持有 | G12: =E12 -> 持仓 | I12: =价格指标计算!B12 -> 3.8037
A13: =RRG趋势计算!A12 -> 44578 | B13: =RRG趋势计算!H12 -> 0 | C13: =价格指标计算!R13 -> 0 | D13: =RRG趋势计算!F12 -> 0 | E13: =IF(OR(B13="",C13="",D13=""),"",IF(D13="上升","持仓",IF(AND(B13="减弱",C13="贵"),"空仓",IF(AND(B13="减弱",C13="中性"),"空仓",IF(AND(B13="改善",C13="贵"),"空仓",IF(B13="滞后","空仓","持仓")))))) -> 持仓 | F13: =IF(OR(B13="",C13="",D13=""),"",IF(D13="上升","趋势上升,趋势溢价持有",IF(AND(B13="减弱",C13="贵"),"趋势减弱+价格贵+下降,卖出",IF(AND(B13="减弱",C13="中性"),"趋势减弱+中性+下降,卖出预警",IF(AND(B13="改善",C13="贵"),"趋势改善+贵+下降,卖出",IF(B13="滞后","趋势滞后+下降,空仓","趋势尚可+下降,持有")))))) -> 趋势尚可+下降,持有 | G13: =E13 -> 持仓 | I13: =价格指标计算!B13 -> 3.7926
A14: =RRG趋势计算!A13 -> 44579 | B14: =RRG趋势计算!H13 -> 0 | C14: =价格指标计算!R14 -> 0 | D14: =RRG趋势计算!F13 -> 0 | E14: =IF(OR(B14="",C14="",D14=""),"",IF(D14="上升","持仓",IF(AND(B14="减弱",C14="贵"),"空仓",IF(AND(B14="减弱",C14="中性"),"空仓",IF(AND(B14="改善",C14="贵"),"空仓",IF(B14="滞后","空仓","持仓")))))) -> 持仓 | F14: =IF(OR(B14="",C14="",D14=""),"",IF(D14="上升","趋势上升,趋势溢价持有",IF(AND(B14="减弱",C14="贵"),"趋势减弱+价格贵+下降,卖出",IF(AND(B14="减弱",C14="中性"),"趋势减弱+中性+下降,卖出预警",IF(AND(B14="改善",C14="贵"),"趋势改善+贵+下降,卖出",IF(B14="滞后","趋势滞后+下降,空仓","趋势尚可+下降,持有")))))) -> 趋势尚可+下降,持有 | G14: =E14 -> 持仓 | I14: =价格指标计算!B14 -> 3.777
A15: =RRG趋势计算!A14 -> 44580 | B15: =RRG趋势计算!H14 -> 0 | C15: =价格指标计算!R15 -> 0 | D15: =RRG趋势计算!F14 -> 0 | E15: =IF(OR(B15="",C15="",D15=""),"",IF(D15="上升","持仓",IF(AND(B15="减弱",C15="贵"),"空仓",IF(AND(B15="减弱",C15="中性"),"空仓",IF(AND(B15="改善",C15="贵"),"空仓",IF(B15="滞后","空仓","持仓")))))) -> 持仓 | F15: =IF(OR(B15="",C15="",D15=""),"",IF(D15="上升","趋势上升,趋势溢价持有",IF(AND(B15="减弱",C15="贵"),"趋势减弱+价格贵+下降,卖出",IF(AND(B15="减弱",C15="中性"),"趋势减弱+中性+下降,卖出预警",IF(AND(B15="改善",C15="贵"),"趋势改善+贵+下降,卖出",IF(B15="滞后","趋势滞后+下降,空仓","趋势尚可+下降,持有")))))) -> 趋势尚可+下降,持有 | G15: =E15 -> 持仓 | I15: =价格指标计算!B15 -> 3.7242
... A44: =RRG趋势计算!A43 -> 44624 | B44: =RRG趋势计算!H43 -> 0 | C44: =价格指标计算!R44 -> 0 | D44: =RRG趋势计算!F43 -> 0 | E44: =IF(OR(B44="",C44="",D44=""),"",IF(D44="上升","持仓",IF(AND(B44="减弱",C44="贵"),"空仓",IF(AND(B44="减弱",C44="中性"),"空仓",IF(AND(B44="改善",C44="贵"),"空仓",IF(B44="滞后","空仓","持仓")))))) -> 持仓 | F44: =IF(OR(B44="",C44="",D44=""),"",IF(D44="上升","趋势上升,趋势溢价持有",IF(AND(B44="减弱",C44="贵"),"趋势减弱+价格贵+下降,卖出",IF(AND(B44="减弱",C44="中性"),"趋势减弱+中性+下降,卖出预警",IF(AND(B44="改善",C44="贵"),"趋势改善+贵+下降,卖出",IF(B44="滞后","趋势滞后+下降,空仓","趋势尚可+下降,持有")))))) -> 趋势尚可+下降,持有 | G44: =E44 -> 持仓 | I44: =价格指标计算!B44 -> 3.8847
A45: =RRG趋势计算!A44 -> 44627 | B45: =RRG趋势计算!H44 -> 0 | C45: =价格指标计算!R45 -> 0 | D45: =RRG趋势计算!F44 -> 0 | E45: =IF(OR(B45="",C45="",D45=""),"",IF(D45="上升","持仓",IF(AND(B45="减弱",C45="贵"),"空仓",IF(AND(B45="减弱",C45="中性"),"空仓",IF(AND(B45="改善",C45="贵"),"空仓",IF(B45="滞后","空仓","持仓")))))) -> 持仓 | F45: =IF(OR(B45="",C45="",D45=""),"",IF(D45="上升","趋势上升,趋势溢价持有",IF(AND(B45="减弱",C45="贵"),"趋势减弱+价格贵+下降,卖出",IF(AND(B45="减弱",C45="中性"),"趋势减弱+中性+下降,卖出预警",IF(AND(B45="改善",C45="贵"),"趋势改善+贵+下降,卖出",IF(B45="滞后","趋势滞后+下降,空仓","趋势尚可+下降,持有")))))) -> 趋势尚可+下降,持有 | G45: =E45 -> 持仓 | I45: =价格指标计算!B45 -> 3.9009 | K45: =RRG趋势计算!D44 -> -0.22860079
A46: =RRG趋势计算!A45 -> 44628 | B46: =RRG趋势计算!H45 -> 0 | C46: =价格指标计算!R46 -> 0 | D46: =RRG趋势计算!F45 -> 0 | E46: =IF(OR(B46="",C46="",D46=""),"",IF(D46="上升","持仓",IF(AND(B46="减弱",C46="贵"),"空仓",IF(AND(B46="减弱",C46="中性"),"空仓",IF(AND(B46="改善",C46="贵"),"空仓",IF(B46="滞后","空仓","持仓")))))) -> 持仓 | F46: =IF(OR(B46="",C46="",D46=""),"",IF(D46="上升","趋势上升,趋势溢价持有",IF(AND(B46="减弱",C46="贵"),"趋势减弱+价格贵+下降,卖出",IF(AND(B46="减弱",C46="中性"),"趋势减弱+中性+下降,卖出预警",IF(AND(B46="改善",C46="贵"),"趋势改善+贵+下降,卖出",IF(B46="滞后","趋势滞后+下降,空仓","趋势尚可+下降,持有")))))) -> 趋势尚可+下降,持有 | G46: =E46 -> 持仓 | I46: =价格指标计算!B46 -> 3.9046 | K46: =RRG趋势计算!D45 -> -0.22591285
A47: =RRG趋势计算!A46 -> 44629 | B47: =RRG趋势计算!H46 -> 0 | C47: =价格指标计算!R47 -> 0 | D47: =RRG趋势计算!F46 -> 0 | E47: =IF(OR(B47="",C47="",D47=""),"",IF(D47="上升","持仓",IF(AND(B47="减弱",C47="贵"),"空仓",IF(AND(B47="减弱",C47="中性"),"空仓",IF(AND(B47="改善",C47="贵"),"空仓",IF(B47="滞后","空仓","持仓")))))) -> 持仓 | F47: =IF(OR(B47="",C47="",D47=""),"",IF(D47="上升","趋势上升,趋势溢价持有",IF(AND(B47="减弱",C47="贵"),"趋势减弱+价格贵+下降,卖出",IF(AND(B47="减弱",C47="中性"),"趋势减弱+中性+下降,卖出预警",IF(AND(B47="改善",C47="贵"),"趋势改善+贵+下降,卖出",IF(B47="滞后","趋势滞后+下降,空仓","趋势尚可+下降,持有")))))) -> 趋势尚可+下降,持有 | G47: =E47 -> 持仓 | I47: =价格指标计算!B47 -> 3.9033 | K47: =RRG趋势计算!D46 -> -0.25870566
A48: =RRG趋势计算!A47 -> 44630 | B48: =RRG趋势计算!H47 -> 0 | C48: =价格指标计算!R48 -> 0 | D48: =RRG趋势计算!F47 -> 0 | E48: =IF(OR(B48="",C48="",D48=""),"",IF(D48="上升","持仓",IF(AND(B48="减弱",C48="贵"),"空仓",IF(AND(B48="减弱",C48="中性"),"空仓",IF(AND(B48="改善",C48="贵"),"空仓",IF(B48="滞后","空仓","持仓")))))) -> 持仓 | F48: =IF(OR(B48="",C48="",D48=""),"",IF(D48="上升","趋势上升,趋势溢价持有",IF(AND(B48="减弱",C48="贵"),"趋势减弱+价格贵+下降,卖出",IF(AND(B48="减弱",C48="中性"),"趋势减弱+中性+下降,卖出预警",IF(AND(B48="改善",C48="贵"),"趋势改善+贵+下降,卖出",IF(B48="滞后","趋势滞后+下降,空仓","趋势尚可+下降,持有")))))) -> 趋势尚可+下降,持有 | G48: =E48 -> 持仓 | I48: =价格指标计算!B48 -> 3.9049 | K48: =RRG趋势计算!D47 -> -0.30908831
A49: =RRG趋势计算!A48 -> 44631 | B49: =RRG趋势计算!H48 -> 0 | C49: =价格指标计算!R49 -> 0 | D49: =RRG趋势计算!F48 -> 0 | E49: =IF(OR(B49="",C49="",D49=""),"",IF(D49="上升","持仓",IF(AND(B49="减弱",C49="贵"),"空仓",IF(AND(B49="减弱",C49="中性"),"空仓",IF(AND(B49="改善",C49="贵"),"空仓",IF(B49="滞后","空仓","持仓")))))) -> 持仓 | F49: =IF(OR(B49="",C49="",D49=""),"",IF(D49="上升","趋势上升,趋势溢价持有",IF(AND(B49="减弱",C49="贵"),"趋势减弱+价格贵+下降,卖出",IF(AND(B49="减弱",C49="中性"),"趋势减弱+中性+下降,卖出预警",IF(AND(B49="改善",C49="贵"),"趋势改善+贵+下降,卖出",IF(B49="滞后","趋势滞后+下降,空仓","趋势尚可+下降,持有")))))) -> 趋势尚可+下降,持有 | G49: =E49 -> 持仓 | I49: =价格指标计算!B49 -> 3.8994 | K49: =RRG趋势计算!D48 -> -0.3297409
A50: =RRG趋势计算!A49 -> 44634 | B50: =RRG趋势计算!H49 -> 0 | C50: =价格指标计算!R50 -> 0 | D50: =RRG趋势计算!F49 -> 0 | E50: =IF(OR(B50="",C50="",D50=""),"",IF(D50="上升","持仓",IF(AND(B50="减弱",C50="贵"),"空仓",IF(AND(B50="减弱",C50="中性"),"空仓",IF(AND(B50="改善",C50="贵"),"空仓",IF(B50="滞后","空仓","持仓")))))) -> 持仓 | F50: =IF(OR(B50="",C50="",D50=""),"",IF(D50="上升","趋势上升,趋势溢价持有",IF(AND(B50="减弱",C50="贵"),"趋势减弱+价格贵+下降,卖出",IF(AND(B50="减弱",C50="中性"),"趋势减弱+中性+下降,卖出预警",IF(AND(B50="改善",C50="贵"),"趋势改善+贵+下降,卖出",IF(B50="滞后","趋势滞后+下降,空仓","趋势尚可+下降,持有")))))) -> 趋势尚可+下降,持有 | G50: =E50 -> 持仓 | I50: =价格指标计算!B50 -> 3.8674 | K50: =RRG趋势计算!D49 -> -0.28822728
A51: =RRG趋势计算!A50 -> 44635 | B51: =RRG趋势计算!H50 -> 0 | C51: =价格指标计算!R51 -> 0 | D51: =RRG趋势计算!F50 -> 0 | E51: =IF(OR(B51="",C51="",D51=""),"",IF(D51="上升","持仓",IF(AND(B51="减弱",C51="贵"),"空仓",IF(AND(B51="减弱",C51="中性"),"空仓",IF(AND(B51="改善",C51="贵"),"空仓",IF(B51="滞后","空仓","持仓")))))) -> 持仓 | F51: =IF(OR(B51="",C51="",D51=""),"",IF(D51="上升","趋势上升,趋势溢价持有",IF(AND(B51="减弱",C51="贵"),"趋势减弱+价格贵+下降,卖出",IF(AND(B51="减弱",C51="中性"),"趋势减弱+中性+下降,卖出预警",IF(AND(B51="改善",C51="贵"),"趋势改善+贵+下降,卖出",IF(B51="滞后","趋势滞后+下降,空仓","趋势尚可+下降,持有")))))) -> 趋势尚可+下降,持有 | G51: =E51 -> 持仓 | I51: =价格指标计算!B51 -> 3.8857 | K51: =RRG趋势计算!D50 -> -0.29622431
A52: =RRG趋势计算!A51 -> 44636 | B52: =RRG趋势计算!H51 -> 0 | C52: =价格指标计算!R52 -> 0 | D52: =RRG趋势计算!F51 -> 0 | E52: =IF(OR(B52="",C52="",D52=""),"",IF(D52="上升","持仓",IF(AND(B52="减弱",C52="贵"),"空仓",IF(AND(B52="减弱",C52="中性"),"空仓",IF(AND(B52="改善",C52="贵"),"空仓",IF(B52="滞后","空仓","持仓")))))) -> 持仓 | F52: =IF(OR(B52="",C52="",D52=""),"",IF(D52="上升","趋势上升,趋势溢价持有",IF(AND(B52="减弱",C52="贵"),"趋势减弱+价格贵+下降,卖出",IF(AND(B52="减弱",C52="中性"),"趋势减弱+中性+下降,卖出预警",IF(AND(B52="改善",C52="贵"),"趋势改善+贵+下降,卖出",IF(B52="滞后","趋势滞后+下降,空仓","趋势尚可+下降,持有")))))) -> 趋势尚可+下降,持有 | G52: =E52 -> 持仓 | I52: =价格指标计算!B52 -> 3.8937 | K52: =RRG趋势计算!D51 -> -0.3339787
A53: =RRG趋势计算!A52 -> 44637 | B53: =RRG趋势计算!H52 -> 0 | C53: =价格指标计算!R53 -> 0 | D53: =RRG趋势计算!F52 -> 0 | E53: =IF(OR(B53="",C53="",D53=""),"",IF(D53="上升","持仓",IF(AND(B53="减弱",C53="贵"),"空仓",IF(AND(B53="减弱",C53="中性"),"空仓",IF(AND(B53="改善",C53="贵"),"空仓",IF(B53="滞后","空仓","持仓")))))) -> 持仓 | F53: =IF(OR(B53="",C53="",D53=""),"",IF(D53="上升","趋势上升,趋势溢价持有",IF(AND(B53="减弱",C53="贵"),"趋势减弱+价格贵+下降,卖出",IF(AND(B53="减弱",C53="中性"),"趋势减弱+中性+下降,卖出预警",IF(AND(B53="改善",C53="贵"),"趋势改善+贵+下降,卖出",IF(B53="滞后","趋势滞后+下降,空仓","趋势尚可+下降,持有")))))) -> 趋势尚可+下降,持有 | G53: =E53 -> 持仓 | I53: =价格指标计算!B53 -> 3.8964 | K53: =RRG趋势计算!D52 -> -0.33314152
A54: =RRG趋势计算!A53 -> 44638 | B54: =RRG趋势计算!H53 -> 0 | C54: =价格指标计算!R54 -> 0 | D54: =RRG趋势计算!F53 -> 0 | E54: =IF(OR(B54="",C54="",D54=""),"",IF(D54="上升","持仓",IF(AND(B54="减弱",C54="贵"),"空仓",IF(AND(B54="减弱",C54="中性"),"空仓",IF(AND(B54="改善",C54="贵"),"空仓",IF(B54="滞后","空仓","持仓")))))) -> 持仓 | F54: =IF(OR(B54="",C54="",D54=""),"",IF(D54="上升","趋势上升,趋势溢价持有",IF(AND(B54="减弱",C54="贵"),"趋势减弱+价格贵+下降,卖出",IF(AND(B54="减弱",C54="中性"),"趋势减弱+中性+下降,卖出预警",IF(AND(B54="改善",C54="贵"),"趋势改善+贵+下降,卖出",IF(B54="滞后","趋势滞后+下降,空仓","趋势尚可+下降,持有")))))) -> 趋势尚可+下降,持有 | G54: =E54 -> 持仓 | I54: =价格指标计算!B54 -> 3.8732 | K54: =RRG趋势计算!D53 -> -0.28355732
A55: =RRG趋势计算!A54 -> 44641 | B55: =RRG趋势计算!H54 -> 0 | C55: =价格指标计算!R55 -> 0 | D55: =RRG趋势计算!F54 -> 0 | E55: =IF(OR(B55="",C55="",D55=""),"",IF(D55="上升","持仓",IF(AND(B55="减弱",C55="贵"),"空仓",IF(AND(B55="减弱",C55="中性"),"空仓",IF(AND(B55="改善",C55="贵"),"空仓",IF(B55="滞后","空仓","持仓")))))) -> 持仓 | F55: =IF(OR(B55="",C55="",D55=""),"",IF(D55="上升","趋势上升,趋势溢价持有",IF(AND(B55="减弱",C55="贵"),"趋势减弱+价格贵+下降,卖出",IF(AND(B55="减弱",C55="中性"),"趋势减弱+中性+下降,卖出预警",IF(AND(B55="改善",C55="贵"),"趋势改善+贵+下降,卖出",IF(B55="滞后","趋势滞后+下降,空仓","趋势尚可+下降,持有")))))) -> 趋势尚可+下降,持有 | G55: =E55 -> 持仓 | I55: =价格指标计算!B55 -> 3.8843 | K55: =RRG趋势计算!D54 -> -0.31623871
A56: =RRG趋势计算!A55 -> 44642 | B56: =RRG趋势计算!H55 -> 0 | C56: =价格指标计算!R56 -> 0 | D56: =RRG趋势计算!F55 -> 0 | E56: =IF(OR(B56="",C56="",D56=""),"",IF(D56="上升","持仓",IF(AND(B56="减弱",C56="贵"),"空仓",IF(AND(B56="减弱",C56="中性"),"空仓",IF(AND(B56="改善",C56="贵"),"空仓",IF(B56="滞后","空仓","持仓")))))) -> 持仓 | F56: =IF(OR(B56="",C56="",D56=""),"",IF(D56="上升","趋势上升,趋势溢价持有",IF(AND(B56="减弱",C56="贵"),"趋势减弱+价格贵+下降,卖出",IF(AND(B56="减弱",C56="中性"),"趋势减弱+中性+下降,卖出预警",IF(AND(B56="改善",C56="贵"),"趋势改善+贵+下降,卖出",IF(B56="滞后","趋势滞后+下降,空仓","趋势尚可+下降,持有")))))) -> 趋势尚可+下降,持有 | G56: =E56 -> 持仓 | I56: =价格指标计算!B56 -> 3.8946 | K56: =RRG趋势计算!D55 -> -0.34405741
A57: =RRG趋势计算!A56 -> 44643 | B57: =RRG趋势计算!H56 -> 0 | C57: =价格指标计算!R57 -> 0 | D57: =RRG趋势计算!F56 -> 0 | E57: =IF(OR(B57="",C57="",D57=""),"",IF(D57="上升","持仓",IF(AND(B57="减弱",C57="贵"),"空仓",IF(AND(B57="减弱",C57="中性"),"空仓",IF(AND(B57="改善",C57="贵"),"空仓",IF(B57="滞后","空仓","持仓")))))) -> 持仓 | F57: =IF(OR(B57="",C57="",D57=""),"",IF(D57="上升","趋势上升,趋势溢价持有",IF(AND(B57="减弱",C57="贵"),"趋势减弱+价格贵+下降,卖出",IF(AND(B57="减弱",C57="中性"),"趋势减弱+中性+下降,卖出预警",IF(AND(B57="改善",C57="贵"),"趋势改善+贵+下降,卖出",IF(B57="滞后","趋势滞后+下降,空仓","趋势尚可+下降,持有")))))) -> 趋势尚可+下降,持有 | G57: =E57 -> 持仓 | I57: =价格指标计算!B57 -> 3.8975 | K57: =RRG趋势计算!D56 -> -0.34964761
A58: =RRG趋势计算!A57 -> 44644 | B58: =RRG趋势计算!H57 -> 0 | C58: =价格指标计算!R58 -> 0 | D58: =RRG趋势计算!F57 -> 0 | E58: =IF(OR(B58="",C58="",D58=""),"",IF(D58="上升","持仓",IF(AND(B58="减弱",C58="贵"),"空仓",IF(AND(B58="减弱",C58="中性"),"空仓",IF(AND(B58="改善",C58="贵"),"空仓",IF(B58="滞后","空仓","持仓")))))) -> 持仓 | F58: =IF(OR(B58="",C58="",D58=""),"",IF(D58="上升","趋势上升,趋势溢价持有",IF(AND(B58="减弱",C58="贵"),"趋势减弱+价格贵+下降,卖出",IF(AND(B58="减弱",C58="中性"),"趋势减弱+中性+下降,卖出预警",IF(AND(B58="改善",C58="贵"),"趋势改善+贵+下降,卖出",IF(B58="滞后","趋势滞后+下降,空仓","趋势尚可+下降,持有")))))) -> 趋势尚可+下降,持有 | G58: =E58 -> 持仓 | I58: =价格指标计算!B58 -> 3.8757 | K58: =RRG趋势计算!D57 -> -0.35116954 | L58: =RRG趋势计算!G57 -> -0.12256875
A59: =RRG趋势计算!A58 -> 44645 | B59: =RRG趋势计算!H58 -> 0 | C59: =价格指标计算!R59 -> 0 | D59: =RRG趋势计算!F58 -> 0 | E59: =IF(OR(B59="",C59="",D59=""),"",IF(D59="上升","持仓",IF(AND(B59="减弱",C59="贵"),"空仓",IF(AND(B59="减弱",C59="中性"),"空仓",IF(AND(B59="改善",C59="贵"),"空仓",IF(B59="滞后","空仓","持仓")))))) -> 持仓 | F59: =IF(OR(B59="",C59="",D59=""),"",IF(D59="上升","趋势上升,趋势溢价持有",IF(AND(B59="减弱",C59="贵"),"趋势减弱+价格贵+下降,卖出",IF(AND(B59="减弱",C59="中性"),"趋势减弱+中性+下降,卖出预警",IF(AND(B59="改善",C59="贵"),"趋势改善+贵+下降,卖出",IF(B59="滞后","趋势滞后+下降,空仓","趋势尚可+下降,持有")))))) -> 趋势尚可+下降,持有 | G59: =E59 -> 持仓 | I59: =价格指标计算!B59 -> 3.8771 | K59: =RRG趋势计算!D58 -> -0.36186546 | L59: =RRG趋势计算!G58 -> -0.13595261
A60: =RRG趋势计算!A59 -> 44648 | B60: =RRG趋势计算!H59 -> 0 | C60: =价格指标计算!R60 -> 0 | D60: =RRG趋势计算!F59 -> 0 | E60: =IF(OR(B60="",C60="",D60=""),"",IF(D60="上升","持仓",IF(AND(B60="减弱",C60="贵"),"空仓",IF(AND(B60="减弱",C60="中性"),"空仓",IF(AND(B60="改善",C60="贵"),"空仓",IF(B60="滞后","空仓","持仓")))))) -> 持仓 | F60: =IF(OR(B60="",C60="",D60=""),"",IF(D60="上升","趋势上升,趋势溢价持有",IF(AND(B60="减弱",C60="贵"),"趋势减弱+价格贵+下降,卖出",IF(AND(B60="减弱",C60="中性"),"趋势减弱+中性+下降,卖出预警",IF(AND(B60="改善",C60="贵"),"趋势改善+贵+下降,卖出",IF(B60="滞后","趋势滞后+下降,空仓","趋势尚可+下降,持有")))))) -> 趋势尚可+下降,持有 | G60: =E60 -> 持仓 | I60: =价格指标计算!B60 -> 3.8854 | K60: =RRG趋势计算!D59 -> -0.3395499 | L60: =RRG趋势计算!G59 -> -0.080844237
A61: =RRG趋势计算!A60 -> 44649 | B61: =RRG趋势计算!H60 -> 0 | C61: =价格指标计算!R61 -> 0 | D61: =RRG趋势计算!F60 -> 0 | E61: =IF(OR(B61="",C61="",D61=""),"",IF(D61="上升","持仓",IF(AND(B61="减弱",C61="贵"),"空仓",IF(AND(B61="减弱",C61="中性"),"空仓",IF(AND(B61="改善",C61="贵"),"空仓",IF(B61="滞后","空仓","持仓")))))) -> 持仓 | F61: =IF(OR(B61="",C61="",D61=""),"",IF(D61="上升","趋势上升,趋势溢价持有",IF(AND(B61="减弱",C61="贵"),"趋势减弱+价格贵+下降,卖出",IF(AND(B61="减弱",C61="中性"),"趋势减弱+中性+下降,卖出预警",IF(AND(B61="改善",C61="贵"),"趋势改善+贵+下降,卖出",IF(B61="滞后","趋势滞后+下降,空仓","趋势尚可+下降,持有")))))) -> 趋势尚可+下降,持有 | G61: =E61 -> 持仓 | I61: =价格指标计算!B61 -> 3.8955 | K61: =RRG趋势计算!D60 -> -0.3361288 | L61: =RRG趋势计算!G60 -> -0.027040485
A62: =RRG趋势计算!A61 -> 44650 | B62: =RRG趋势计算!H61 -> 0 | C62: =价格指标计算!R62 -> 0 | D62: =RRG趋势计算!F61 -> 0 | E62: =IF(OR(B62="",C62="",D62=""),"",IF(D62="上升","持仓",IF(AND(B62="减弱",C62="贵"),"空仓",IF(AND(B62="减弱",C62="中性"),"空仓",IF(AND(B62="改善",C62="贵"),"空仓",IF(B62="滞后","空仓","持仓")))))) -> 持仓 | F62: =IF(OR(B62="",C62="",D62=""),"",IF(D62="上升","趋势上升,趋势溢价持有",IF(AND(B62="减弱",C62="贵"),"趋势减弱+价格贵+下降,卖出",IF(AND(B62="减弱",C62="中性"),"趋势减弱+中性+下降,卖出预警",IF(AND(B62="改善",C62="贵"),"趋势改善+贵+下降,卖出",IF(B62="滞后","趋势滞后+下降,空仓","趋势尚可+下降,持有")))))) -> 趋势尚可+下降,持有 | G62: =E62 -> 持仓 | I62: =价格指标计算!B62 -> 3.8902 | K62: =RRG趋势计算!D61 -> -0.30211781 | L62: =RRG趋势计算!G61 -> 0.027623091
A63: =RRG趋势计算!A62 -> 44651 | B63: =RRG趋势计算!H62 -> 0 | C63: =价格指标计算!R63 -> 0 | D63: =RRG趋势计算!F62 -> 0 | E63: =IF(OR(B63="",C63="",D63=""),"",IF(D63="上升","持仓",IF(AND(B63="减弱",C63="贵"),"空仓",IF(AND(B63="减弱",C63="中性"),"空仓",IF(AND(B63="改善",C63="贵"),"空仓",IF(B63="滞后","空仓","持仓")))))) -> 持仓 | F63: =IF(OR(B63="",C63="",D63=""),"",IF(D63="上升","趋势上升,趋势溢价持有",IF(AND(B63="减弱",C63="贵"),"趋势减弱+价格贵+下降,卖出",IF(AND(B63="减弱",C63="中性"),"趋势减弱+中性+下降,卖出预警",IF(AND(B63="改善",C63="贵"),"趋势改善+贵+下降,卖出",IF(B63="滞后","趋势滞后+下降,空仓","趋势尚可+下降,持有")))))) -> 趋势尚可+下降,持有 | G63: =E63 -> 持仓 | I63: =价格指标计算!B63 -> 3.8888 | K63: =RRG趋势计算!D62 -> -0.25008223 | L63: =RRG趋势计算!G62 -> 0.038145048
A64: =RRG趋势计算!A63 -> 44652 | B64: =RRG趋势计算!H63 -> 0 | C64: =价格指标计算!R64 -> 0 | D64: =RRG趋势计算!F63 -> 0 | E64: =IF(OR(B64="",C64="",D64=""),"",IF(D64="上升","持仓",IF(AND(B64="减弱",C64="贵"),"空仓",IF(AND(B64="减弱",C64="中性"),"空仓",IF(AND(B64="改善",C64="贵"),"空仓",IF(B64="滞后","空仓","持仓")))))) -> 持仓 | F64: =IF(OR(B64="",C64="",D64=""),"",IF(D64="上升","趋势上升,趋势溢价持有",IF(AND(B64="减弱",C64="贵"),"趋势减弱+价格贵+下降,卖出",IF(AND(B64="减弱",C64="中性"),"趋势减弱+中性+下降,卖出预警",IF(AND(B64="改善",C64="贵"),"趋势改善+贵+下降,卖出",IF(B64="滞后","趋势滞后+下降,空仓","趋势尚可+下降,持有")))))) -> 趋势尚可+下降,持有 | G64: =E64 -> 持仓 | I64: =价格指标计算!B64 -> 3.8802 | K64: =RRG趋势计算!D63 -> -0.2024419 | L64: =RRG趋势计算!G63 -> 0.093782416
A65: =RRG趋势计算!A64 -> 44653 | B65: =RRG趋势计算!H64 -> 改善 | C65: =价格指标计算!R65 -> 0 | D65: =RRG趋势计算!F64 -> 下降 | E65: =IF(OR(B65="",C65="",D65=""),"",IF(D65="上升","持仓",IF(AND(B65="减弱",C65="贵"),"空仓",IF(AND(B65="减弱",C65="中性"),"空仓",IF(AND(B65="改善",C65="贵"),"空仓",IF(B65="滞后","空仓","持仓")))))) -> 持仓 | F65: =IF(OR(B65="",C65="",D65=""),"",IF(D65="上升","趋势上升,趋势溢价持有",IF(AND(B65="减弱",C65="贵"),"趋势减弱+价格贵+下降,卖出",IF(AND(B65="减弱",C65="中性"),"趋势减弱+中性+下降,卖出预警",IF(AND(B65="改善",C65="贵"),"趋势改善+贵+下降,卖出",IF(B65="滞后","趋势滞后+下降,空仓","趋势尚可+下降,持有")))))) -> 趋势尚可+下降,持有 | G65: =E65 -> 持仓 | I65: =价格指标计算!B65 -> 3.8802 | K65: =RRG趋势计算!D64 -> -0.19203087 | L65: =RRG趋势计算!G64 -> 0.14194784
A66: =RRG趋势计算!A65 -> 44657 | B66: =RRG趋势计算!H65 -> 改善 | C66: =价格指标计算!R66 -> 0 | D66: =RRG趋势计算!F65 -> 下降 | E66: =IF(OR(B66="",C66="",D66=""),"",IF(D66="上升","持仓",IF(AND(B66="减弱",C66="贵"),"空仓",IF(AND(B66="减弱",C66="中性"),"空仓",IF(AND(B66="改善",C66="贵"),"空仓",IF(B66="滞后","空仓","持仓")))))) -> 持仓 | F66: =IF(OR(B66="",C66="",D66=""),"",IF(D66="上升","趋势上升,趋势溢价持有",IF(AND(B66="减弱",C66="贵"),"趋势减弱+价格贵+下降,卖出",IF(AND(B66="减弱",C66="中性"),"趋势减弱+中性+下降,卖出预警",IF(AND(B66="改善",C66="贵"),"趋势改善+贵+下降,卖出",IF(B66="滞后","趋势滞后+下降,空仓","趋势尚可+下降,持有")))))) -> 趋势尚可+下降,持有 | G66: =E66 -> 持仓 | I66: =价格指标计算!B66 -> 3.8744 | K66: =RRG趋势计算!D65 -> -0.15477074 | L66: =RRG趋势计算!G65 -> 0.17837078
A67: =RRG趋势计算!A66 -> 44658 | B67: =RRG趋势计算!H66 -> 改善 | C67: =价格指标计算!R67 -> 0 | D67: =RRG趋势计算!F66 -> 下降 | E67: =IF(OR(B67="",C67="",D67=""),"",IF(D67="上升","持仓",IF(AND(B67="减弱",C67="贵"),"空仓",IF(AND(B67="减弱",C67="中性"),"空仓",IF(AND(B67="改善",C67="贵"),"空仓",IF(B67="滞后","空仓","持仓")))))) -> 持仓 | F67: =IF(OR(B67="",C67="",D67=""),"",IF(D67="上升","趋势上升,趋势溢价持有",IF(AND(B67="减弱",C67="贵"),"趋势减弱+价格贵+下降,卖出",IF(AND(B67="减弱",C67="中性"),"趋势减弱+中性+下降,卖出预警",IF(AND(B67="改善",C67="贵"),"趋势改善+贵+下降,卖出",IF(B67="滞后","趋势滞后+下降,空仓","趋势尚可+下降,持有")))))) -> 趋势尚可+下降,持有 | G67: =E67 -> 持仓 | I67: =价格指标计算!B67 -> 3.862 | K67: =RRG趋势计算!D66 -> -0.073438733 | L67: =RRG趋势计算!G66 -> 0.21011859
A68: =RRG趋势计算!A67 -> 44659 | B68: =RRG趋势计算!H67 -> 改善 | C68: =价格指标计算!R68 -> 0 | D68: =RRG趋势计算!F67 -> 下降 | E68: =IF(OR(B68="",C68="",D68=""),"",IF(D68="上升","持仓",IF(AND(B68="减弱",C68="贵"),"空仓",IF(AND(B68="减弱",C68="中性"),"空仓",IF(AND(B68="改善",C68="贵"),"空仓",IF(B68="滞后","空仓","持仓")))))) -> 持仓 | F68: =IF(OR(B68="",C68="",D68=""),"",IF(D68="上升","趋势上升,趋势溢价持有",IF(AND(B68="减弱",C68="贵"),"趋势减弱+价格贵+下降,卖出",IF(AND(B68="减弱",C68="中性"),"趋势减弱+中性+下降,卖出预警",IF(AND(B68="改善",C68="贵"),"趋势改善+贵+下降,卖出",IF(B68="滞后","趋势滞后+下降,空仓","趋势尚可+下降,持有")))))) -> 趋势尚可+下降,持有 | G68: =E68 -> 持仓 | I68: =价格指标计算!B68 -> 3.8459 | K68: =RRG趋势计算!D67 -> -0.014111369 | L68: =RRG趋势计算!G67 -> 0.30212734
...

Sheet 信号矩阵表
A1: 状态矩阵完整对照表 - 趋势象限 × 价格区间 × 趋势方向
A3: 象限\价格区间 | B3: 便宜(>=55%) | C3: 中性(15~55%) | D3: 贵(<15%)
A4: 【趋势上升】趋势溢价 - 无论象限价格均持仓
A5: 领先 | B5: 持仓 | C5: 持仓 | D5: 持仓
A6: 改善 | B6: 持仓 | C6: 持仓 | D6: 持仓
A7: 减弱 | B7: 持仓 | C7: 持仓 | D7: 持仓
A8: 滞后 | B8: 持仓 | C8: 持仓 | D8: 持仓
A9: 【趋势下降】按矩阵严格判断
A10: 领先 | B10: 持仓 | C10: 持仓 | D10: 谨慎持仓
A11: 改善 | B11: 持仓 | C11: 持仓 | D11: 空仓
A12: 减弱 | B12: 持仓 | C12: 空仓 | D12: 空仓
A13: 滞后 | B13: 空仓 | C13: 空仓 | D13: 空仓
A15: 设计原则
A16: 核心逻辑 | B16: 趋势方向作为"总开关":上升趋势时趋势溢价持有,下降趋势时按矩阵严格判断
A17: 买入逻辑 | B17: 右侧买入:趋势领先/改善时买入,不抄底
A18: 卖出逻辑 | B18: 左侧卖出:趋势减弱+价格贵/中性时提前卖出,滞后时清仓
A19: 趋势溢价 | B19: 大趋势上升时即使象限转弱或价格偏贵也持有,避免牛市过早下车
A20: 确认机制 | B20: 信号需连续3天确认才转换,过滤噪声
A21: 流动性考虑 | B21: 长信用流动性差,交易成本高,低频交易(年均约3次)
A22: 险资适配 | B22: 不亏钱优先,空仓期可配置货基/短债,持仓期享受资本利得+票息
A23: 分位数定义 | B23: 便宜>=55% 中性15~55% 贵<15% (PERCENTRANK.EXC计算252日历史分位)
A24: RRG参数 | B24: X轴=比值偏离42日MA的程度,Y轴=X轴14日变化,四象限:领先/改善/减弱/滞后
A26: 业绩表现
A27: 目标时间段 | B27: 交易次数 | C27: 持仓天数 | D27: 空仓天数 | E27: 覆盖率% | F27: 策略收益% | G27: 买入持有% | H27: 超额收益% | I27: 评价
A28: 2023/1-2023/8 | B28: 0 | C28: 167 | D28: 0 | E28: 100 | F28: 0.55 | I28: 优秀
A29: 2024/1-2024/8 | B29: 0 | C29: 168 | D29: 0 | E29: 100 | F29: 0.95 | I29: 优秀
A30: 2024/11-2025/2 | B30: 2 | C30: 77 | D30: 4 | E30: 95.1 | F30: 0.26 | I30: 优秀
A31: 2025/4-2025/7 | B31: 0 | C31: 84 | D31: 0 | E31: 100 | F31: 0.21 | I31: 优秀
A32: 2026/1以来 | B32: 1 | C32: 94 | D32: 8 | E32: 92.2 | F32: 0.34 | I32: 优秀
